Watching for file changes with StatReloader
Performing system checks...

System check identified no issues (0 silenced).
March 07, 2024 - 11:40:38
Django version 4.1, using settings 'cancer_prediction_backend.settings'
Starting development server at http://127.0.0.1:8000/
Quit the server with CONTROL-C.
Watching for file changes with StatReloader
Not Found: /
[07/Mar/2024 11:40:55] "GET / HTTP/1.1" 404 2295
[07/Mar/2024 11:40:57] "GET /admin/login/?next=/admin/ HTTP/1.1" 200 2218
Not Found: /user
[07/Mar/2024 11:41:03] "GET /user HTTP/1.1" 404 2325
Not Found: /user/
[07/Mar/2024 11:41:07] "GET /user/ HTTP/1.1" 404 2571
[07/Mar/2024 11:42:26] "POST /admin/login/?next=/admin/ HTTP/1.1" 302 0
[07/Mar/2024 11:42:26] "GET /admin/ HTTP/1.1" 200 4471
[07/Mar/2024 11:42:26] "GET /static/admin/css/dashboard.css HTTP/1.1" 200 380
[07/Mar/2024 11:42:26] "GET /static/admin/img/icon-addlink.svg HTTP/1.1" 200 331
[07/Mar/2024 11:42:26] "GET /static/admin/img/icon-changelink.svg HTTP/1.1" 200 380
[07/Mar/2024 11:42:26] "GET /static/admin/fonts/Roboto-Bold-webfont.woff HTTP/1.1" 200 86184
[07/Mar/2024 11:42:31] "GET /admin/auth/group/ HTTP/1.1" 200 5958
[07/Mar/2024 11:42:31] "GET /static/admin/css/changelists.css HTTP/1.1" 200 6395
[07/Mar/2024 11:42:31] "GET /static/admin/img/search.svg HTTP/1.1" 200 458
[07/Mar/2024 11:42:31] "GET /static/admin/js/admin/RelatedObjectLookups.js HTTP/1.1" 200 8919
[07/Mar/2024 11:42:31] "GET /static/admin/js/jquery.init.js HTTP/1.1" 200 347
[07/Mar/2024 11:42:31] "GET /static/admin/js/core.js HTTP/1.1" 200 5698
[07/Mar/2024 11:42:31] "GET /static/admin/js/actions.js HTTP/1.1" 200 7872
[07/Mar/2024 11:42:31] "GET /static/admin/js/urlify.js HTTP/1.1" 200 7902
[07/Mar/2024 11:42:31] "GET /static/admin/js/vendor/jquery/jquery.js HTTP/1.1" 200 288580
[07/Mar/2024 11:42:31] "GET /static/admin/js/prepopulate.js HTTP/1.1" 200 1531
[07/Mar/2024 11:42:31] "GET /admin/jsi18n/ HTTP/1.1" 200 3343
[07/Mar/2024 11:42:31] "GET /static/admin/js/vendor/xregexp/xregexp.js HTTP/1.1" 200 232381
[07/Mar/2024 11:42:31] "GET /static/admin/js/filters.js HTTP/1.1" 200 966
[07/Mar/2024 11:42:31] "GET /static/admin/img/tooltag-add.svg HTTP/1.1" 200 331
[07/Mar/2024 11:42:33] "GET /admin/ HTTP/1.1" 200 4471
[07/Mar/2024 11:42:34] "GET /admin/medicalCase/case/ HTTP/1.1" 200 5630
[07/Mar/2024 11:42:34] "GET /admin/jsi18n/ HTTP/1.1" 200 3343
[07/Mar/2024 11:42:35] "GET /admin/ HTTP/1.1" 200 4471
[07/Mar/2024 11:42:36] "GET /admin/user/user/ HTTP/1.1" 200 9955
[07/Mar/2024 11:42:36] "GET /static/admin/img/icon-yes.svg HTTP/1.1" 200 436
[07/Mar/2024 11:42:36] "GET /static/admin/img/icon-no.svg HTTP/1.1" 200 560
[07/Mar/2024 11:42:36] "GET /admin/jsi18n/ HTTP/1.1" 200 3343
[07/Mar/2024 11:42:36] "GET /static/admin/img/sorting-icons.svg HTTP/1.1" 200 1097
[07/Mar/2024 11:42:39] "GET /admin/user/user/3/change/ HTTP/1.1" 200 17061
[07/Mar/2024 11:42:39] "GET /static/admin/css/forms.css HTTP/1.1" 200 8944
[07/Mar/2024 11:42:39] "GET /static/admin/js/prepopulate_init.js HTTP/1.1" 200 586
[07/Mar/2024 11:42:39] "GET /static/admin/js/SelectBox.js HTTP/1.1" 200 4360
[07/Mar/2024 11:42:39] "GET /static/admin/js/SelectFilter2.js HTTP/1.1" 200 11317
[07/Mar/2024 11:42:39] "GET /static/admin/js/calendar.js HTTP/1.1" 200 8466
[07/Mar/2024 11:42:39] "GET /static/admin/js/admin/DateTimeShortcuts.js HTTP/1.1" 200 19379
[07/Mar/2024 11:42:39] "GET /static/admin/css/widgets.css HTTP/1.1" 200 11297
[07/Mar/2024 11:42:39] "GET /admin/jsi18n/ HTTP/1.1" 200 3343
[07/Mar/2024 11:42:39] "GET /static/admin/js/change_form.js HTTP/1.1" 200 1043
[07/Mar/2024 11:42:39] "GET /static/admin/img/selector-icons.svg HTTP/1.1" 200 3291
[07/Mar/2024 11:42:39] "GET /static/admin/img/icon-unknown.svg HTTP/1.1" 200 655
[07/Mar/2024 11:42:39] "GET /static/admin/img/icon-unknown-alt.svg HTTP/1.1" 200 655
[07/Mar/2024 11:42:39] "GET /static/admin/img/icon-clock.svg HTTP/1.1" 200 677
[07/Mar/2024 11:42:39] "GET /static/admin/img/icon-calendar.svg HTTP/1.1" 200 1086
[07/Mar/2024 11:42:48] "POST /admin/user/user/3/change/ HTTP/1.1" 302 0
[07/Mar/2024 11:42:48] "GET /admin/user/user/ HTTP/1.1" 200 10123
[07/Mar/2024 11:42:48] "GET /admin/jsi18n/ HTTP/1.1" 200 3343
[07/Mar/2024 11:42:53] "GET /admin/user/user/1/change/ HTTP/1.1" 200 17013
[07/Mar/2024 11:42:53] "GET /admin/jsi18n/ HTTP/1.1" 200 3343
[07/Mar/2024 11:42:54] "GET /admin/user/user/ HTTP/1.1" 200 9932
Not Found: /medicalCase
[07/Mar/2024 11:44:51] "GET /medicalCase HTTP/1.1" 404 2346
Not Found: /medicalCase/
[07/Mar/2024 11:44:53] "GET /medicalCase/ HTTP/1.1" 404 2627
Method Not Allowed (GET): /medicalCase/upload_picture/
[07/Mar/2024 11:44:59] "GET /medicalCase/upload_picture/ HTTP/1.1" 405 0
Method Not Allowed (GET): /medicalCase/upload_picture/
[07/Mar/2024 11:45:01] "GET /medicalCase/upload_picture/ HTTP/1.1" 405 0
[07/Mar/2024 11:46:21] "GET /medicalCase/get_schedule HTTP/1.1" 301 0
[07/Mar/2024 11:46:21] "GET /medicalCase/get_schedule/ HTTP/1.1" 200 1636
[07/Mar/2024 12:02:30] "GET /admin/medicalCase/case/ HTTP/1.1" 200 5630
[07/Mar/2024 12:02:30] "GET /admin/jsi18n/ HTTP/1.1" 200 3343
[07/Mar/2024 12:02:32] "GET /admin/medicalCase/case/add/ HTTP/1.1" 200 7286
[07/Mar/2024 12:02:32] "GET /static/admin/img/icon-viewlink.svg HTTP/1.1" 200 581
[07/Mar/2024 12:02:32] "GET /admin/jsi18n/ HTTP/1.1" 200 3343
[07/Mar/2024 12:02:42] "GET /admin/auth/group/ HTTP/1.1" 200 5958
[07/Mar/2024 12:02:42] "GET /admin/jsi18n/ HTTP/1.1" 200 3343
[07/Mar/2024 12:02:44] "GET /admin/medicalCase/case/ HTTP/1.1" 200 5630
[07/Mar/2024 12:02:44] "GET /admin/jsi18n/ HTTP/1.1" 200 3343
[07/Mar/2024 12:02:45] "GET /admin/medicalCase/case/add/ HTTP/1.1" 200 7286
[07/Mar/2024 12:02:45] "GET /admin/jsi18n/ HTTP/1.1" 200 3343
[07/Mar/2024 12:02:47] "POST /admin/medicalCase/case/add/ HTTP/1.1" 200 7429
[07/Mar/2024 12:02:47] "GET /admin/jsi18n/ HTTP/1.1" 200 3343
[07/Mar/2024 12:02:50] "POST /admin/medicalCase/case/add/ HTTP/1.1" 302 0
[07/Mar/2024 12:02:50] "GET /admin/medicalCase/case/ HTTP/1.1" 200 6992
[07/Mar/2024 12:02:51] "GET /admin/jsi18n/ HTTP/1.1" 200 3343
[07/Mar/2024 12:02:52] "GET /admin/medicalCase/case/1/change/ HTTP/1.1" 200 7558
[07/Mar/2024 12:02:52] "GET /admin/jsi18n/ HTTP/1.1" 200 3343
/mnt/d/MyFileAtD/cancer-prediction/apps/medicalCase/models.py changed, reloading.
Performing system checks...

System check identified no issues (0 silenced).
March 07, 2024 - 11:40:51
Django version 4.1, using settings 'cancer_prediction_backend.settings'
Starting development server at http://127.0.0.1:8000/
Quit the server with CONTROL-C.
Watching for file changes with StatReloader
[07/Mar/2024 12:03:14] "GET /admin/ HTTP/1.1" 200 5076
[07/Mar/2024 12:03:16] "GET /admin/ HTTP/1.1" 200 5076
Not Found: /
[07/Mar/2024 12:03:18] "GET / HTTP/1.1" 404 2295
[07/Mar/2024 12:03:19] "GET /admin/ HTTP/1.1" 200 5076
/mnt/d/MyFileAtD/cancer-prediction/apps/medicalCase/admin.py changed, reloading.
Performing system checks...

System check identified no issues (0 silenced).
March 07, 2024 - 12:03:10
Django version 4.1, using settings 'cancer_prediction_backend.settings'
Starting development server at http://127.0.0.1:8000/
Quit the server with CONTROL-C.
Watching for file changes with StatReloader
Not Found: /
[07/Mar/2024 12:08:57] "GET / HTTP/1.1" 404 2295
[07/Mar/2024 12:09:01] "GET /admin/ HTTP/1.1" 200 5506
[07/Mar/2024 12:09:03] "GET /admin/medicalCase/image/ HTTP/1.1" 200 5933
[07/Mar/2024 12:09:03] "GET /admin/jsi18n/ HTTP/1.1" 200 3343
[07/Mar/2024 12:09:04] "GET /admin/medicalCase/image/add/ HTTP/1.1" 200 8020
[07/Mar/2024 12:09:04] "GET /admin/jsi18n/ HTTP/1.1" 200 3343
[07/Mar/2024 12:09:13] "POST /admin/medicalCase/image/add/ HTTP/1.1" 302 0
[07/Mar/2024 12:09:13] "GET /admin/medicalCase/image/ HTTP/1.1" 200 7302
[07/Mar/2024 12:09:13] "GET /admin/jsi18n/ HTTP/1.1" 200 3343
[07/Mar/2024 12:09:14] "GET /admin/medicalCase/image/1/change/ HTTP/1.1" 200 8401
[07/Mar/2024 12:09:14] "GET /admin/jsi18n/ HTTP/1.1" 200 3343
Not Found: /images/下载.jfif
[07/Mar/2024 12:09:17] "GET /images/%E4%B8%8B%E8%BD%BD.jfif HTTP/1.1" 404 2379
[07/Mar/2024 12:09:25] "GET /admin/medicalCase/image/1/change/ HTTP/1.1" 200 8401
Not Found: /images/下载.jfif
[07/Mar/2024 12:09:33] "GET /images/%E4%B8%8B%E8%BD%BD.jfif HTTP/1.1" 404 2379
[07/Mar/2024 12:09:33] "GET /admin/medicalCase/image/1/change/ HTTP/1.1" 200 8401
Performing system checks...

System check identified no issues (0 silenced).
March 07, 2024 - 12:08:53
Django version 4.1, using settings 'cancer_prediction_backend.settings'
Starting development server at http://127.0.0.1:8000/
Quit the server with CONTROL-C.
Watching for file changes with StatReloader
Performing system checks...

System check identified no issues (0 silenced).
March 08, 2024 - 06:06:12
Django version 4.1, using settings 'cancer_prediction_backend.settings'
Starting development server at http://127.0.0.1:8000/
Quit the server with CONTROL-C.
nohup: ignoring input
Watching for file changes with StatReloader
Not Found: /
[08/Mar/2024 06:06:33] "GET / HTTP/1.1" 404 2295
Not Found: /favicon.ico
[08/Mar/2024 06:06:33] "GET /favicon.ico HTTP/1.1" 404 2346
[08/Mar/2024 06:06:36] "GET /admin/ HTTP/1.1" 200 5803
[08/Mar/2024 06:08:32] "GET /admin/medicalCase/image/ HTTP/1.1" 200 7091
[08/Mar/2024 06:08:32] "GET /admin/jsi18n/ HTTP/1.1" 200 3343
[08/Mar/2024 06:08:35] "GET /admin/medicalCase/image/1/change/ HTTP/1.1" 200 8401
[08/Mar/2024 06:08:35] "GET /admin/jsi18n/ HTTP/1.1" 200 3343
Not Found: /images/下载.jfif
[08/Mar/2024 06:08:40] "GET /images/%E4%B8%8B%E8%BD%BD.jfif HTTP/1.1" 404 2379
[08/Mar/2024 06:08:41] "GET /admin/medicalCase/image/1/change/ HTTP/1.1" 200 8401
/mnt/d/MyFileAtD/cancer-prediction/cancer_prediction_backend/settings.py changed, reloading.
Performing system checks...

System check identified no issues (0 silenced).
March 08, 2024 - 06:06:29
Django version 4.1, using settings 'cancer_prediction_backend.settings'
Starting development server at http://127.0.0.1:8000/
Quit the server with CONTROL-C.
Watching for file changes with StatReloader
System check identified some issues:

WARNINGS:
?: (staticfiles.W004) The directory '/mnt/d/MyFileAtD/cancer-prediction/static' in the STATICFILES_DIRS setting does not exist.

System check identified 1 issue (0 silenced).
/mnt/d/MyFileAtD/cancer-prediction/cancer_prediction_backend/urls.py changed, reloading.
Performing system checks...

March 08, 2024 - 06:26:27
Django version 4.1, using settings 'cancer_prediction_backend.settings'
Starting development server at http://127.0.0.1:8000/
Quit the server with CONTROL-C.
Watching for file changes with StatReloader
Exception in thread django-main-thread:
Traceback (most recent call last):
  File "/home/wnico/anaconda3/envs/frb5/lib/python3.10/threading.py", line 1016, in _bootstrap_inner
    self.run()
  File "/home/wnico/anaconda3/envs/frb5/lib/python3.10/threading.py", line 953, in run
    self._target(*self._args, **self._kwargs)
  File "/home/wnico/anaconda3/envs/frb5/lib/python3.10/site-packages/django/utils/autoreload.py", line 64, in wrapper
    fn(*args, **kwargs)
  File "/home/wnico/anaconda3/envs/frb5/lib/python3.10/site-packages/django/core/management/commands/runserver.py", line 134, in inner_run
    self.check(display_num_errors=True)
  File "/home/wnico/anaconda3/envs/frb5/lib/python3.10/site-packages/django/core/management/base.py", line 475, in check
    all_issues = checks.run_checks(
  File "/home/wnico/anaconda3/envs/frb5/lib/python3.10/site-packages/django/core/checks/registry.py", line 88, in run_checks
    new_errors = check(app_configs=app_configs, databases=databases)
  File "/home/wnico/anaconda3/envs/frb5/lib/python3.10/site-packages/django/core/checks/urls.py", line 14, in check_url_config
    return check_resolver(resolver)
  File "/home/wnico/anaconda3/envs/frb5/lib/python3.10/site-packages/django/core/checks/urls.py", line 24, in check_resolver
    return check_method()
  File "/home/wnico/anaconda3/envs/frb5/lib/python3.10/site-packages/django/urls/resolvers.py", line 476, in check
    for pattern in self.url_patterns:
  File "/home/wnico/anaconda3/envs/frb5/lib/python3.10/site-packages/django/utils/functional.py", line 57, in __get__
    res = instance.__dict__[self.name] = self.func(instance)
  File "/home/wnico/anaconda3/envs/frb5/lib/python3.10/site-packages/django/urls/resolvers.py", line 690, in url_patterns
    patterns = getattr(self.urlconf_module, "urlpatterns", self.urlconf_module)
  File "/home/wnico/anaconda3/envs/frb5/lib/python3.10/site-packages/django/utils/functional.py", line 57, in __get__
    res = instance.__dict__[self.name] = self.func(instance)
  File "/home/wnico/anaconda3/envs/frb5/lib/python3.10/site-packages/django/urls/resolvers.py", line 683, in urlconf_module
    return import_module(self.urlconf_name)
  File "/home/wnico/anaconda3/envs/frb5/lib/python3.10/importlib/__init__.py", line 126, in import_module
    return _bootstrap._gcd_import(name[level:], package, level)
  File "<frozen importlib._bootstrap>", line 1050, in _gcd_import
  File "<frozen importlib._bootstrap>", line 1027, in _find_and_load
  File "<frozen importlib._bootstrap>", line 1006, in _find_and_load_unlocked
  File "<frozen importlib._bootstrap>", line 688, in _load_unlocked
  File "<frozen importlib._bootstrap_external>", line 883, in exec_module
  File "<frozen importlib._bootstrap>", line 241, in _call_with_frames_removed
  File "/mnt/d/MyFileAtD/cancer-prediction/cancer_prediction_backend/urls.py", line 18, in <module>
    from django.conf.urls import url
ImportError: cannot import name 'url' from 'django.conf.urls' (/home/wnico/anaconda3/envs/frb5/lib/python3.10/site-packages/django/conf/urls/__init__.py)
/mnt/d/MyFileAtD/cancer-prediction/cancer_prediction_backend/urls.py changed, reloading.
Performing system checks...

Watching for file changes with StatReloader
Exception in thread django-main-thread:
Traceback (most recent call last):
  File "/home/wnico/anaconda3/envs/frb5/lib/python3.10/threading.py", line 1016, in _bootstrap_inner
    self.run()
  File "/home/wnico/anaconda3/envs/frb5/lib/python3.10/threading.py", line 953, in run
    self._target(*self._args, **self._kwargs)
  File "/home/wnico/anaconda3/envs/frb5/lib/python3.10/site-packages/django/utils/autoreload.py", line 64, in wrapper
    fn(*args, **kwargs)
  File "/home/wnico/anaconda3/envs/frb5/lib/python3.10/site-packages/django/core/management/commands/runserver.py", line 134, in inner_run
    self.check(display_num_errors=True)
  File "/home/wnico/anaconda3/envs/frb5/lib/python3.10/site-packages/django/core/management/base.py", line 475, in check
    all_issues = checks.run_checks(
  File "/home/wnico/anaconda3/envs/frb5/lib/python3.10/site-packages/django/core/checks/registry.py", line 88, in run_checks
    new_errors = check(app_configs=app_configs, databases=databases)
  File "/home/wnico/anaconda3/envs/frb5/lib/python3.10/site-packages/django/core/checks/urls.py", line 14, in check_url_config
    return check_resolver(resolver)
  File "/home/wnico/anaconda3/envs/frb5/lib/python3.10/site-packages/django/core/checks/urls.py", line 24, in check_resolver
    return check_method()
  File "/home/wnico/anaconda3/envs/frb5/lib/python3.10/site-packages/django/urls/resolvers.py", line 476, in check
    for pattern in self.url_patterns:
  File "/home/wnico/anaconda3/envs/frb5/lib/python3.10/site-packages/django/utils/functional.py", line 57, in __get__
    res = instance.__dict__[self.name] = self.func(instance)
  File "/home/wnico/anaconda3/envs/frb5/lib/python3.10/site-packages/django/urls/resolvers.py", line 690, in url_patterns
    patterns = getattr(self.urlconf_module, "urlpatterns", self.urlconf_module)
  File "/home/wnico/anaconda3/envs/frb5/lib/python3.10/site-packages/django/utils/functional.py", line 57, in __get__
    res = instance.__dict__[self.name] = self.func(instance)
  File "/home/wnico/anaconda3/envs/frb5/lib/python3.10/site-packages/django/urls/resolvers.py", line 683, in urlconf_module
    return import_module(self.urlconf_name)
  File "/home/wnico/anaconda3/envs/frb5/lib/python3.10/importlib/__init__.py", line 126, in import_module
    return _bootstrap._gcd_import(name[level:], package, level)
  File "<frozen importlib._bootstrap>", line 1050, in _gcd_import
  File "<frozen importlib._bootstrap>", line 1027, in _find_and_load
  File "<frozen importlib._bootstrap>", line 1006, in _find_and_load_unlocked
  File "<frozen importlib._bootstrap>", line 688, in _load_unlocked
  File "<frozen importlib._bootstrap_external>", line 883, in exec_module
  File "<frozen importlib._bootstrap>", line 241, in _call_with_frames_removed
  File "/mnt/d/MyFileAtD/cancer-prediction/cancer_prediction_backend/urls.py", line 18, in <module>
    from django.conf.urls import url
ImportError: cannot import name 'url' from 'django.conf.urls' (/home/wnico/anaconda3/envs/frb5/lib/python3.10/site-packages/django/conf/urls/__init__.py)
/mnt/d/MyFileAtD/cancer-prediction/cancer_prediction_backend/urls.py changed, reloading.
Performing system checks...

Watching for file changes with StatReloader
Exception in thread django-main-thread:
Traceback (most recent call last):
  File "/home/wnico/anaconda3/envs/frb5/lib/python3.10/threading.py", line 1016, in _bootstrap_inner
    self.run()
  File "/home/wnico/anaconda3/envs/frb5/lib/python3.10/threading.py", line 953, in run
    self._target(*self._args, **self._kwargs)
  File "/home/wnico/anaconda3/envs/frb5/lib/python3.10/site-packages/django/utils/autoreload.py", line 64, in wrapper
    fn(*args, **kwargs)
  File "/home/wnico/anaconda3/envs/frb5/lib/python3.10/site-packages/django/core/management/commands/runserver.py", line 134, in inner_run
    self.check(display_num_errors=True)
  File "/home/wnico/anaconda3/envs/frb5/lib/python3.10/site-packages/django/core/management/base.py", line 475, in check
    all_issues = checks.run_checks(
  File "/home/wnico/anaconda3/envs/frb5/lib/python3.10/site-packages/django/core/checks/registry.py", line 88, in run_checks
    new_errors = check(app_configs=app_configs, databases=databases)
  File "/home/wnico/anaconda3/envs/frb5/lib/python3.10/site-packages/django/core/checks/urls.py", line 14, in check_url_config
    return check_resolver(resolver)
  File "/home/wnico/anaconda3/envs/frb5/lib/python3.10/site-packages/django/core/checks/urls.py", line 24, in check_resolver
    return check_method()
  File "/home/wnico/anaconda3/envs/frb5/lib/python3.10/site-packages/django/urls/resolvers.py", line 476, in check
    for pattern in self.url_patterns:
  File "/home/wnico/anaconda3/envs/frb5/lib/python3.10/site-packages/django/utils/functional.py", line 57, in __get__
    res = instance.__dict__[self.name] = self.func(instance)
  File "/home/wnico/anaconda3/envs/frb5/lib/python3.10/site-packages/django/urls/resolvers.py", line 690, in url_patterns
    patterns = getattr(self.urlconf_module, "urlpatterns", self.urlconf_module)
  File "/home/wnico/anaconda3/envs/frb5/lib/python3.10/site-packages/django/utils/functional.py", line 57, in __get__
    res = instance.__dict__[self.name] = self.func(instance)
  File "/home/wnico/anaconda3/envs/frb5/lib/python3.10/site-packages/django/urls/resolvers.py", line 683, in urlconf_module
    return import_module(self.urlconf_name)
  File "/home/wnico/anaconda3/envs/frb5/lib/python3.10/importlib/__init__.py", line 126, in import_module
    return _bootstrap._gcd_import(name[level:], package, level)
  File "<frozen importlib._bootstrap>", line 1050, in _gcd_import
  File "<frozen importlib._bootstrap>", line 1027, in _find_and_load
  File "<frozen importlib._bootstrap>", line 1006, in _find_and_load_unlocked
  File "<frozen importlib._bootstrap>", line 688, in _load_unlocked
  File "<frozen importlib._bootstrap_external>", line 883, in exec_module
  File "<frozen importlib._bootstrap>", line 241, in _call_with_frames_removed
  File "/mnt/d/MyFileAtD/cancer-prediction/cancer_prediction_backend/urls.py", line 18, in <module>
    from django.conf.urls import url
ImportError: cannot import name 'url' from 'django.conf.urls' (/home/wnico/anaconda3/envs/frb5/lib/python3.10/site-packages/django/conf/urls/__init__.py)
/mnt/d/MyFileAtD/cancer-prediction/cancer_prediction_backend/urls.py changed, reloading.
Performing system checks...

Watching for file changes with StatReloader
Exception in thread django-main-thread:
Traceback (most recent call last):
  File "/home/wnico/anaconda3/envs/frb5/lib/python3.10/threading.py", line 1016, in _bootstrap_inner
    self.run()
  File "/home/wnico/anaconda3/envs/frb5/lib/python3.10/threading.py", line 953, in run
    self._target(*self._args, **self._kwargs)
  File "/home/wnico/anaconda3/envs/frb5/lib/python3.10/site-packages/django/utils/autoreload.py", line 64, in wrapper
    fn(*args, **kwargs)
  File "/home/wnico/anaconda3/envs/frb5/lib/python3.10/site-packages/django/core/management/commands/runserver.py", line 134, in inner_run
    self.check(display_num_errors=True)
  File "/home/wnico/anaconda3/envs/frb5/lib/python3.10/site-packages/django/core/management/base.py", line 475, in check
    all_issues = checks.run_checks(
  File "/home/wnico/anaconda3/envs/frb5/lib/python3.10/site-packages/django/core/checks/registry.py", line 88, in run_checks
    new_errors = check(app_configs=app_configs, databases=databases)
  File "/home/wnico/anaconda3/envs/frb5/lib/python3.10/site-packages/django/core/checks/urls.py", line 14, in check_url_config
    return check_resolver(resolver)
  File "/home/wnico/anaconda3/envs/frb5/lib/python3.10/site-packages/django/core/checks/urls.py", line 24, in check_resolver
    return check_method()
  File "/home/wnico/anaconda3/envs/frb5/lib/python3.10/site-packages/django/urls/resolvers.py", line 476, in check
    for pattern in self.url_patterns:
  File "/home/wnico/anaconda3/envs/frb5/lib/python3.10/site-packages/django/utils/functional.py", line 57, in __get__
    res = instance.__dict__[self.name] = self.func(instance)
  File "/home/wnico/anaconda3/envs/frb5/lib/python3.10/site-packages/django/urls/resolvers.py", line 690, in url_patterns
    patterns = getattr(self.urlconf_module, "urlpatterns", self.urlconf_module)
  File "/home/wnico/anaconda3/envs/frb5/lib/python3.10/site-packages/django/utils/functional.py", line 57, in __get__
    res = instance.__dict__[self.name] = self.func(instance)
  File "/home/wnico/anaconda3/envs/frb5/lib/python3.10/site-packages/django/urls/resolvers.py", line 683, in urlconf_module
    return import_module(self.urlconf_name)
  File "/home/wnico/anaconda3/envs/frb5/lib/python3.10/importlib/__init__.py", line 126, in import_module
    return _bootstrap._gcd_import(name[level:], package, level)
  File "<frozen importlib._bootstrap>", line 1050, in _gcd_import
  File "<frozen importlib._bootstrap>", line 1027, in _find_and_load
  File "<frozen importlib._bootstrap>", line 1006, in _find_and_load_unlocked
  File "<frozen importlib._bootstrap>", line 688, in _load_unlocked
  File "<frozen importlib._bootstrap_external>", line 883, in exec_module
  File "<frozen importlib._bootstrap>", line 241, in _call_with_frames_removed
  File "/mnt/d/MyFileAtD/cancer-prediction/cancer_prediction_backend/urls.py", line 18, in <module>
    from django.conf.urls import url
ImportError: cannot import name 'url' from 'django.conf.urls' (/home/wnico/anaconda3/envs/frb5/lib/python3.10/site-packages/django/conf/urls/__init__.py)
/mnt/d/MyFileAtD/cancer-prediction/cancer_prediction_backend/urls.py changed, reloading.
Performing system checks...

Watching for file changes with StatReloader
Exception in thread django-main-thread:
Traceback (most recent call last):
  File "/home/wnico/anaconda3/envs/frb5/lib/python3.10/threading.py", line 1016, in _bootstrap_inner
    self.run()
  File "/home/wnico/anaconda3/envs/frb5/lib/python3.10/threading.py", line 953, in run
    self._target(*self._args, **self._kwargs)
  File "/home/wnico/anaconda3/envs/frb5/lib/python3.10/site-packages/django/utils/autoreload.py", line 64, in wrapper
    fn(*args, **kwargs)
  File "/home/wnico/anaconda3/envs/frb5/lib/python3.10/site-packages/django/core/management/commands/runserver.py", line 134, in inner_run
    self.check(display_num_errors=True)
  File "/home/wnico/anaconda3/envs/frb5/lib/python3.10/site-packages/django/core/management/base.py", line 475, in check
    all_issues = checks.run_checks(
  File "/home/wnico/anaconda3/envs/frb5/lib/python3.10/site-packages/django/core/checks/registry.py", line 88, in run_checks
    new_errors = check(app_configs=app_configs, databases=databases)
  File "/home/wnico/anaconda3/envs/frb5/lib/python3.10/site-packages/django/core/checks/urls.py", line 14, in check_url_config
    return check_resolver(resolver)
  File "/home/wnico/anaconda3/envs/frb5/lib/python3.10/site-packages/django/core/checks/urls.py", line 24, in check_resolver
    return check_method()
  File "/home/wnico/anaconda3/envs/frb5/lib/python3.10/site-packages/django/urls/resolvers.py", line 476, in check
    for pattern in self.url_patterns:
  File "/home/wnico/anaconda3/envs/frb5/lib/python3.10/site-packages/django/utils/functional.py", line 57, in __get__
    res = instance.__dict__[self.name] = self.func(instance)
  File "/home/wnico/anaconda3/envs/frb5/lib/python3.10/site-packages/django/urls/resolvers.py", line 690, in url_patterns
    patterns = getattr(self.urlconf_module, "urlpatterns", self.urlconf_module)
  File "/home/wnico/anaconda3/envs/frb5/lib/python3.10/site-packages/django/utils/functional.py", line 57, in __get__
    res = instance.__dict__[self.name] = self.func(instance)
  File "/home/wnico/anaconda3/envs/frb5/lib/python3.10/site-packages/django/urls/resolvers.py", line 683, in urlconf_module
    return import_module(self.urlconf_name)
  File "/home/wnico/anaconda3/envs/frb5/lib/python3.10/importlib/__init__.py", line 126, in import_module
    return _bootstrap._gcd_import(name[level:], package, level)
  File "<frozen importlib._bootstrap>", line 1050, in _gcd_import
  File "<frozen importlib._bootstrap>", line 1027, in _find_and_load
  File "<frozen importlib._bootstrap>", line 1006, in _find_and_load_unlocked
  File "<frozen importlib._bootstrap>", line 688, in _load_unlocked
  File "<frozen importlib._bootstrap_external>", line 883, in exec_module
  File "<frozen importlib._bootstrap>", line 241, in _call_with_frames_removed
  File "/mnt/d/MyFileAtD/cancer-prediction/cancer_prediction_backend/urls.py", line 18, in <module>
    from django.conf.urls import url
ImportError: cannot import name 'url' from 'django.conf.urls' (/home/wnico/anaconda3/envs/frb5/lib/python3.10/site-packages/django/conf/urls/__init__.py)
/mnt/d/MyFileAtD/cancer-prediction/cancer_prediction_backend/urls.py changed, reloading.
Performing system checks...

Watching for file changes with StatReloader
Exception in thread django-main-thread:
Traceback (most recent call last):
  File "/home/wnico/anaconda3/envs/frb5/lib/python3.10/threading.py", line 1016, in _bootstrap_inner
    self.run()
  File "/home/wnico/anaconda3/envs/frb5/lib/python3.10/threading.py", line 953, in run
    self._target(*self._args, **self._kwargs)
  File "/home/wnico/anaconda3/envs/frb5/lib/python3.10/site-packages/django/utils/autoreload.py", line 64, in wrapper
    fn(*args, **kwargs)
  File "/home/wnico/anaconda3/envs/frb5/lib/python3.10/site-packages/django/core/management/commands/runserver.py", line 134, in inner_run
    self.check(display_num_errors=True)
  File "/home/wnico/anaconda3/envs/frb5/lib/python3.10/site-packages/django/core/management/base.py", line 475, in check
    all_issues = checks.run_checks(
  File "/home/wnico/anaconda3/envs/frb5/lib/python3.10/site-packages/django/core/checks/registry.py", line 88, in run_checks
    new_errors = check(app_configs=app_configs, databases=databases)
  File "/home/wnico/anaconda3/envs/frb5/lib/python3.10/site-packages/django/core/checks/urls.py", line 14, in check_url_config
    return check_resolver(resolver)
  File "/home/wnico/anaconda3/envs/frb5/lib/python3.10/site-packages/django/core/checks/urls.py", line 24, in check_resolver
    return check_method()
  File "/home/wnico/anaconda3/envs/frb5/lib/python3.10/site-packages/django/urls/resolvers.py", line 476, in check
    for pattern in self.url_patterns:
  File "/home/wnico/anaconda3/envs/frb5/lib/python3.10/site-packages/django/utils/functional.py", line 57, in __get__
    res = instance.__dict__[self.name] = self.func(instance)
  File "/home/wnico/anaconda3/envs/frb5/lib/python3.10/site-packages/django/urls/resolvers.py", line 690, in url_patterns
    patterns = getattr(self.urlconf_module, "urlpatterns", self.urlconf_module)
  File "/home/wnico/anaconda3/envs/frb5/lib/python3.10/site-packages/django/utils/functional.py", line 57, in __get__
    res = instance.__dict__[self.name] = self.func(instance)
  File "/home/wnico/anaconda3/envs/frb5/lib/python3.10/site-packages/django/urls/resolvers.py", line 683, in urlconf_module
    return import_module(self.urlconf_name)
  File "/home/wnico/anaconda3/envs/frb5/lib/python3.10/importlib/__init__.py", line 126, in import_module
    return _bootstrap._gcd_import(name[level:], package, level)
  File "<frozen importlib._bootstrap>", line 1050, in _gcd_import
  File "<frozen importlib._bootstrap>", line 1027, in _find_and_load
  File "<frozen importlib._bootstrap>", line 1006, in _find_and_load_unlocked
  File "<frozen importlib._bootstrap>", line 688, in _load_unlocked
  File "<frozen importlib._bootstrap_external>", line 883, in exec_module
  File "<frozen importlib._bootstrap>", line 241, in _call_with_frames_removed
  File "/mnt/d/MyFileAtD/cancer-prediction/cancer_prediction_backend/urls.py", line 18, in <module>
    from django.conf.urls import url
ImportError: cannot import name 'url' from 'django.conf.urls' (/home/wnico/anaconda3/envs/frb5/lib/python3.10/site-packages/django/conf/urls/__init__.py)
/mnt/d/MyFileAtD/cancer-prediction/cancer_prediction_backend/urls.py changed, reloading.
Performing system checks...

Watching for file changes with StatReloader
Exception in thread django-main-thread:
Traceback (most recent call last):
  File "/home/wnico/anaconda3/envs/frb5/lib/python3.10/threading.py", line 1016, in _bootstrap_inner
    self.run()
  File "/home/wnico/anaconda3/envs/frb5/lib/python3.10/threading.py", line 953, in run
    self._target(*self._args, **self._kwargs)
  File "/home/wnico/anaconda3/envs/frb5/lib/python3.10/site-packages/django/utils/autoreload.py", line 64, in wrapper
    fn(*args, **kwargs)
  File "/home/wnico/anaconda3/envs/frb5/lib/python3.10/site-packages/django/core/management/commands/runserver.py", line 134, in inner_run
    self.check(display_num_errors=True)
  File "/home/wnico/anaconda3/envs/frb5/lib/python3.10/site-packages/django/core/management/base.py", line 475, in check
    all_issues = checks.run_checks(
  File "/home/wnico/anaconda3/envs/frb5/lib/python3.10/site-packages/django/core/checks/registry.py", line 88, in run_checks
    new_errors = check(app_configs=app_configs, databases=databases)
  File "/home/wnico/anaconda3/envs/frb5/lib/python3.10/site-packages/django/core/checks/urls.py", line 14, in check_url_config
    return check_resolver(resolver)
  File "/home/wnico/anaconda3/envs/frb5/lib/python3.10/site-packages/django/core/checks/urls.py", line 24, in check_resolver
    return check_method()
  File "/home/wnico/anaconda3/envs/frb5/lib/python3.10/site-packages/django/urls/resolvers.py", line 476, in check
    for pattern in self.url_patterns:
  File "/home/wnico/anaconda3/envs/frb5/lib/python3.10/site-packages/django/utils/functional.py", line 57, in __get__
    res = instance.__dict__[self.name] = self.func(instance)
  File "/home/wnico/anaconda3/envs/frb5/lib/python3.10/site-packages/django/urls/resolvers.py", line 690, in url_patterns
    patterns = getattr(self.urlconf_module, "urlpatterns", self.urlconf_module)
  File "/home/wnico/anaconda3/envs/frb5/lib/python3.10/site-packages/django/utils/functional.py", line 57, in __get__
    res = instance.__dict__[self.name] = self.func(instance)
  File "/home/wnico/anaconda3/envs/frb5/lib/python3.10/site-packages/django/urls/resolvers.py", line 683, in urlconf_module
    return import_module(self.urlconf_name)
  File "/home/wnico/anaconda3/envs/frb5/lib/python3.10/importlib/__init__.py", line 126, in import_module
    return _bootstrap._gcd_import(name[level:], package, level)
  File "<frozen importlib._bootstrap>", line 1050, in _gcd_import
  File "<frozen importlib._bootstrap>", line 1027, in _find_and_load
  File "<frozen importlib._bootstrap>", line 1006, in _find_and_load_unlocked
  File "<frozen importlib._bootstrap>", line 688, in _load_unlocked
  File "<frozen importlib._bootstrap_external>", line 883, in exec_module
  File "<frozen importlib._bootstrap>", line 241, in _call_with_frames_removed
  File "/mnt/d/MyFileAtD/cancer-prediction/cancer_prediction_backend/urls.py", line 18, in <module>
    from django.conf.urls import url
ImportError: cannot import name 'url' from 'django.conf.urls' (/home/wnico/anaconda3/envs/frb5/lib/python3.10/site-packages/django/conf/urls/__init__.py)
/mnt/d/MyFileAtD/cancer-prediction/cancer_prediction_backend/urls.py changed, reloading.
Performing system checks...

Watching for file changes with StatReloader
System check identified some issues:

WARNINGS:
?: (staticfiles.W004) The directory '/mnt/d/MyFileAtD/cancer-prediction/static' in the STATICFILES_DIRS setting does not exist.

System check identified 1 issue (0 silenced).
[08/Mar/2024 07:08:59] "GET /admin/ HTTP/1.1" 200 5803
[08/Mar/2024 07:09:01] "GET /admin/medicalCase/image/ HTTP/1.1" 200 7091
[08/Mar/2024 07:09:01] "GET /admin/jsi18n/ HTTP/1.1" 200 3343
[08/Mar/2024 07:09:28] "GET /static/ HTTP/1.1" 404 1767
/mnt/d/MyFileAtD/cancer-prediction/cancer_prediction_backend/urls.py changed, reloading.
Performing system checks...

March 08, 2024 - 07:08:58
Django version 4.1, using settings 'cancer_prediction_backend.settings'
Starting development server at http://127.0.0.1:8000/
Quit the server with CONTROL-C.
Watching for file changes with StatReloader
System check identified some issues:

WARNINGS:
?: (2_0.W001) Your URL pattern 'media/(?P<path>.*)' has a route that contains '(?P<', begins with a '^', or ends with a '$'. This was likely an oversight when migrating to django.urls.path().
?: (staticfiles.W004) The directory '/mnt/d/MyFileAtD/cancer-prediction/static' in the STATICFILES_DIRS setting does not exist.

System check identified 2 issues (0 silenced).
[08/Mar/2024 07:09:52] "GET /admin/medicalCase/image/ HTTP/1.1" 200 7091
[08/Mar/2024 07:09:53] "GET /admin/jsi18n/ HTTP/1.1" 200 3343
[08/Mar/2024 07:09:54] "GET /admin/medicalCase/image/1/change/ HTTP/1.1" 200 8401
[08/Mar/2024 07:09:54] "GET /admin/jsi18n/ HTTP/1.1" 200 3343
Not Found: /images/下载.jfif
[08/Mar/2024 07:09:55] "GET /images/%E4%B8%8B%E8%BD%BD.jfif HTTP/1.1" 404 2503
[08/Mar/2024 07:10:00] "GET /admin/medicalCase/image/1/change/ HTTP/1.1" 200 8401
/mnt/d/MyFileAtD/cancer-prediction/apps/medicalCase/api/interaction.py changed, reloading.
Performing system checks...

March 08, 2024 - 07:09:51
Django version 4.1, using settings 'cancer_prediction_backend.settings'
Starting development server at http://127.0.0.1:8000/
Quit the server with CONTROL-C.
Watching for file changes with StatReloader
System check identified some issues:

WARNINGS:
?: (2_0.W001) Your URL pattern 'media/(?P<path>.*)' has a route that contains '(?P<', begins with a '^', or ends with a '$'. This was likely an oversight when migrating to django.urls.path().
?: (staticfiles.W004) The directory '/mnt/d/MyFileAtD/cancer-prediction/static' in the STATICFILES_DIRS setting does not exist.

System check identified 2 issues (0 silenced).
/mnt/d/MyFileAtD/cancer-prediction/apps/medicalCase/api/interaction.py changed, reloading.
Performing system checks...

March 08, 2024 - 09:21:24
Django version 4.1, using settings 'cancer_prediction_backend.settings'
Starting development server at http://127.0.0.1:8000/
Quit the server with CONTROL-C.
Watching for file changes with StatReloader
System check identified some issues:

WARNINGS:
?: (2_0.W001) Your URL pattern 'media/(?P<path>.*)' has a route that contains '(?P<', begins with a '^', or ends with a '$'. This was likely an oversight when migrating to django.urls.path().
?: (staticfiles.W004) The directory '/mnt/d/MyFileAtD/cancer-prediction/static' in the STATICFILES_DIRS setting does not exist.

System check identified 2 issues (0 silenced).
Internal Server Error: /medicalCase/upload_picture/
Traceback (most recent call last):
  File "/home/wnico/anaconda3/envs/frb5/lib/python3.10/site-packages/django/utils/datastructures.py", line 84, in __getitem__
    list_ = super().__getitem__(key)
KeyError: 'file'

During handling of the above exception, another exception occurred:

Traceback (most recent call last):
  File "/home/wnico/anaconda3/envs/frb5/lib/python3.10/site-packages/django/core/handlers/exception.py", line 55, in inner
    response = get_response(request)
  File "/home/wnico/anaconda3/envs/frb5/lib/python3.10/site-packages/django/core/handlers/base.py", line 197, in _get_response
    response = wrapped_callback(request, *callback_args, **callback_kwargs)
  File "/home/wnico/anaconda3/envs/frb5/lib/python3.10/site-packages/django/views/decorators/http.py", line 43, in inner
    return func(request, *args, **kwargs)
  File "/mnt/d/MyFileAtD/cancer-prediction/apps/medicalCase/api/interaction.py", line 32, in upload_picture
    if request.FILES['file']:
  File "/home/wnico/anaconda3/envs/frb5/lib/python3.10/site-packages/django/utils/datastructures.py", line 86, in __getitem__
    raise MultiValueDictKeyError(key)
django.utils.datastructures.MultiValueDictKeyError: 'file'
[08/Mar/2024 09:24:03] "POST /medicalCase/upload_picture/ HTTP/1.1" 500 76684
Internal Server Error: /medicalCase/upload_picture/
Traceback (most recent call last):
  File "/home/wnico/anaconda3/envs/frb5/lib/python3.10/site-packages/django/utils/datastructures.py", line 84, in __getitem__
    list_ = super().__getitem__(key)
KeyError: 'file'

During handling of the above exception, another exception occurred:

Traceback (most recent call last):
  File "/home/wnico/anaconda3/envs/frb5/lib/python3.10/site-packages/django/core/handlers/exception.py", line 55, in inner
    response = get_response(request)
  File "/home/wnico/anaconda3/envs/frb5/lib/python3.10/site-packages/django/core/handlers/base.py", line 197, in _get_response
    response = wrapped_callback(request, *callback_args, **callback_kwargs)
  File "/home/wnico/anaconda3/envs/frb5/lib/python3.10/site-packages/django/views/decorators/http.py", line 43, in inner
    return func(request, *args, **kwargs)
  File "/mnt/d/MyFileAtD/cancer-prediction/apps/medicalCase/api/interaction.py", line 32, in upload_picture
    if request.FILES['file']:
  File "/home/wnico/anaconda3/envs/frb5/lib/python3.10/site-packages/django/utils/datastructures.py", line 86, in __getitem__
    raise MultiValueDictKeyError(key)
django.utils.datastructures.MultiValueDictKeyError: 'file'
[08/Mar/2024 09:24:36] "POST /medicalCase/upload_picture/ HTTP/1.1" 500 76684
/mnt/d/MyFileAtD/cancer-prediction/apps/medicalCase/api/interaction.py changed, reloading.
Performing system checks...

March 08, 2024 - 09:21:36
Django version 4.1, using settings 'cancer_prediction_backend.settings'
Starting development server at http://127.0.0.1:8000/
Quit the server with CONTROL-C.
<WSGIRequest: POST '/medicalCase/upload_picture/'>
<WSGIRequest: POST '/medicalCase/upload_picture/'>
Watching for file changes with StatReloader
System check identified some issues:

WARNINGS:
?: (2_0.W001) Your URL pattern 'media/(?P<path>.*)' has a route that contains '(?P<', begins with a '^', or ends with a '$'. This was likely an oversight when migrating to django.urls.path().
?: (staticfiles.W004) The directory '/mnt/d/MyFileAtD/cancer-prediction/static' in the STATICFILES_DIRS setting does not exist.

System check identified 2 issues (0 silenced).
Not Implemented: /medicalCase/upload_picture/
[08/Mar/2024 09:25:17] "POST /medicalCase/upload_picture/ HTTP/1.1" 501 22
/mnt/d/MyFileAtD/cancer-prediction/apps/medicalCase/api/interaction.py changed, reloading.
Performing system checks...

March 08, 2024 - 09:25:17
Django version 4.1, using settings 'cancer_prediction_backend.settings'
Starting development server at http://127.0.0.1:8000/
Quit the server with CONTROL-C.
<WSGIRequest: POST '/medicalCase/upload_picture/'>
Watching for file changes with StatReloader
System check identified some issues:

WARNINGS:
?: (2_0.W001) Your URL pattern 'media/(?P<path>.*)' has a route that contains '(?P<', begins with a '^', or ends with a '$'. This was likely an oversight when migrating to django.urls.path().
?: (staticfiles.W004) The directory '/mnt/d/MyFileAtD/cancer-prediction/static' in the STATICFILES_DIRS setting does not exist.

System check identified 2 issues (0 silenced).
Not Implemented: /medicalCase/upload_picture/
[08/Mar/2024 09:25:35] "POST /medicalCase/upload_picture/ HTTP/1.1" 501 48
/mnt/d/MyFileAtD/cancer-prediction/apps/medicalCase/api/interaction.py changed, reloading.
Performing system checks...

March 08, 2024 - 09:25:34
Django version 4.1, using settings 'cancer_prediction_backend.settings'
Starting development server at http://127.0.0.1:8000/
Quit the server with CONTROL-C.
<WSGIRequest: POST '/medicalCase/upload_picture/'>
Watching for file changes with StatReloader
System check identified some issues:

WARNINGS:
?: (2_0.W001) Your URL pattern 'media/(?P<path>.*)' has a route that contains '(?P<', begins with a '^', or ends with a '$'. This was likely an oversight when migrating to django.urls.path().
?: (staticfiles.W004) The directory '/mnt/d/MyFileAtD/cancer-prediction/static' in the STATICFILES_DIRS setting does not exist.

System check identified 2 issues (0 silenced).
/mnt/d/MyFileAtD/cancer-prediction/apps/medicalCase/api/interaction.py changed, reloading.
Performing system checks...

March 08, 2024 - 09:25:46
Django version 4.1, using settings 'cancer_prediction_backend.settings'
Starting development server at http://127.0.0.1:8000/
Quit the server with CONTROL-C.
Watching for file changes with StatReloader
System check identified some issues:

WARNINGS:
?: (2_0.W001) Your URL pattern 'media/(?P<path>.*)' has a route that contains '(?P<', begins with a '^', or ends with a '$'. This was likely an oversight when migrating to django.urls.path().
?: (staticfiles.W004) The directory '/mnt/d/MyFileAtD/cancer-prediction/static' in the STATICFILES_DIRS setting does not exist.

System check identified 2 issues (0 silenced).
/mnt/d/MyFileAtD/cancer-prediction/apps/medicalCase/api/interaction.py changed, reloading.
Performing system checks...

March 08, 2024 - 09:26:35
Django version 4.1, using settings 'cancer_prediction_backend.settings'
Starting development server at http://127.0.0.1:8000/
Quit the server with CONTROL-C.
Watching for file changes with StatReloader
System check identified some issues:

WARNINGS:
?: (2_0.W001) Your URL pattern 'media/(?P<path>.*)' has a route that contains '(?P<', begins with a '^', or ends with a '$'. This was likely an oversight when migrating to django.urls.path().
?: (staticfiles.W004) The directory '/mnt/d/MyFileAtD/cancer-prediction/static' in the STATICFILES_DIRS setting does not exist.

System check identified 2 issues (0 silenced).
/mnt/d/MyFileAtD/cancer-prediction/apps/medicalCase/api/interaction.py changed, reloading.
Performing system checks...

March 08, 2024 - 09:26:38
Django version 4.1, using settings 'cancer_prediction_backend.settings'
Starting development server at http://127.0.0.1:8000/
Quit the server with CONTROL-C.
Watching for file changes with StatReloader
System check identified some issues:

WARNINGS:
?: (2_0.W001) Your URL pattern 'media/(?P<path>.*)' has a route that contains '(?P<', begins with a '^', or ends with a '$'. This was likely an oversight when migrating to django.urls.path().
?: (staticfiles.W004) The directory '/mnt/d/MyFileAtD/cancer-prediction/static' in the STATICFILES_DIRS setting does not exist.

System check identified 2 issues (0 silenced).
/mnt/d/MyFileAtD/cancer-prediction/apps/medicalCase/api/interaction.py changed, reloading.
Performing system checks...

March 08, 2024 - 09:26:41
Django version 4.1, using settings 'cancer_prediction_backend.settings'
Starting development server at http://127.0.0.1:8000/
Quit the server with CONTROL-C.
Watching for file changes with StatReloader
System check identified some issues:

WARNINGS:
?: (2_0.W001) Your URL pattern 'media/(?P<path>.*)' has a route that contains '(?P<', begins with a '^', or ends with a '$'. This was likely an oversight when migrating to django.urls.path().
?: (staticfiles.W004) The directory '/mnt/d/MyFileAtD/cancer-prediction/static' in the STATICFILES_DIRS setting does not exist.

System check identified 2 issues (0 silenced).
Not Implemented: /medicalCase/upload_picture/
[08/Mar/2024 09:26:53] "POST /medicalCase/upload_picture/ HTTP/1.1" 501 48
/mnt/d/MyFileAtD/cancer-prediction/apps/medicalCase/api/interaction.py changed, reloading.
Performing system checks...

March 08, 2024 - 09:26:52
Django version 4.1, using settings 'cancer_prediction_backend.settings'
Starting development server at http://127.0.0.1:8000/
Quit the server with CONTROL-C.
<WSGIRequest: POST '/medicalCase/upload_picture/'>
Watching for file changes with StatReloader
System check identified some issues:

WARNINGS:
?: (2_0.W001) Your URL pattern 'media/(?P<path>.*)' has a route that contains '(?P<', begins with a '^', or ends with a '$'. This was likely an oversight when migrating to django.urls.path().
?: (staticfiles.W004) The directory '/mnt/d/MyFileAtD/cancer-prediction/static' in the STATICFILES_DIRS setting does not exist.

System check identified 2 issues (0 silenced).
/mnt/d/MyFileAtD/cancer-prediction/apps/medicalCase/api/interaction.py changed, reloading.
Performing system checks...

March 08, 2024 - 09:27:27
Django version 4.1, using settings 'cancer_prediction_backend.settings'
Starting development server at http://127.0.0.1:8000/
Quit the server with CONTROL-C.
Watching for file changes with StatReloader
System check identified some issues:

WARNINGS:
?: (2_0.W001) Your URL pattern 'media/(?P<path>.*)' has a route that contains '(?P<', begins with a '^', or ends with a '$'. This was likely an oversight when migrating to django.urls.path().
?: (staticfiles.W004) The directory '/mnt/d/MyFileAtD/cancer-prediction/static' in the STATICFILES_DIRS setting does not exist.

System check identified 2 issues (0 silenced).
Not Implemented: /medicalCase/upload_picture/
[08/Mar/2024 09:27:37] "POST /medicalCase/upload_picture/ HTTP/1.1" 501 48
/mnt/d/MyFileAtD/cancer-prediction/apps/medicalCase/api/interaction.py changed, reloading.
Performing system checks...

March 08, 2024 - 09:27:37
Django version 4.1, using settings 'cancer_prediction_backend.settings'
Starting development server at http://127.0.0.1:8000/
Quit the server with CONTROL-C.
<MultiValueDict: {}>
Watching for file changes with StatReloader
System check identified some issues:

WARNINGS:
?: (2_0.W001) Your URL pattern 'media/(?P<path>.*)' has a route that contains '(?P<', begins with a '^', or ends with a '$'. This was likely an oversight when migrating to django.urls.path().
?: (staticfiles.W004) The directory '/mnt/d/MyFileAtD/cancer-prediction/static' in the STATICFILES_DIRS setting does not exist.

System check identified 2 issues (0 silenced).
Not Implemented: /medicalCase/upload_picture/
[08/Mar/2024 09:28:24] "POST /medicalCase/upload_picture/ HTTP/1.1" 501 48
Not Implemented: /medicalCase/upload_picture/
[08/Mar/2024 09:39:04] "POST /medicalCase/upload_picture/ HTTP/1.1" 501 48
/mnt/d/MyFileAtD/cancer-prediction/apps/medicalCase/api/interaction.py changed, reloading.
Performing system checks...

March 08, 2024 - 09:28:23
Django version 4.1, using settings 'cancer_prediction_backend.settings'
Starting development server at http://127.0.0.1:8000/
Quit the server with CONTROL-C.
entering upload_picture
<MultiValueDict: {}>
entering upload_picture
<MultiValueDict: {}>
Watching for file changes with StatReloader
System check identified some issues:

WARNINGS:
?: (2_0.W001) Your URL pattern 'media/(?P<path>.*)' has a route that contains '(?P<', begins with a '^', or ends with a '$'. This was likely an oversight when migrating to django.urls.path().

System check identified 1 issue (0 silenced).
Not Implemented: /medicalCase/upload_picture/
[08/Mar/2024 09:39:20] "POST /medicalCase/upload_picture/ HTTP/1.1" 501 48
/mnt/d/MyFileAtD/cancer-prediction/apps/medicalCase/api/interaction.py changed, reloading.
Performing system checks...

March 08, 2024 - 09:39:20
Django version 4.1, using settings 'cancer_prediction_backend.settings'
Starting development server at http://127.0.0.1:8000/
Quit the server with CONTROL-C.
entering upload_picture
Watching for file changes with StatReloader
System check identified some issues:

WARNINGS:
?: (2_0.W001) Your URL pattern 'media/(?P<path>.*)' has a route that contains '(?P<', begins with a '^', or ends with a '$'. This was likely an oversight when migrating to django.urls.path().

System check identified 1 issue (0 silenced).
Not Implemented: /medicalCase/upload_picture/
[08/Mar/2024 09:40:22] "POST /medicalCase/upload_picture/ HTTP/1.1" 501 48
Not Implemented: /medicalCase/upload_picture/
[08/Mar/2024 09:41:47] "POST /medicalCase/upload_picture/ HTTP/1.1" 501 48
/mnt/d/MyFileAtD/cancer-prediction/apps/medicalCase/api/interaction.py changed, reloading.
Performing system checks...

March 08, 2024 - 09:40:03
Django version 4.1, using settings 'cancer_prediction_backend.settings'
Starting development server at http://127.0.0.1:8000/
Quit the server with CONTROL-C.
entering upload_picture
entering upload_picture
Watching for file changes with StatReloader
System check identified some issues:

WARNINGS:
?: (2_0.W001) Your URL pattern 'media/(?P<path>.*)' has a route that contains '(?P<', begins with a '^', or ends with a '$'. This was likely an oversight when migrating to django.urls.path().

System check identified 1 issue (0 silenced).
/mnt/d/MyFileAtD/cancer-prediction/apps/medicalCase/api/interaction.py changed, reloading.
Performing system checks...

March 08, 2024 - 09:42:43
Django version 4.1, using settings 'cancer_prediction_backend.settings'
Starting development server at http://127.0.0.1:8000/
Quit the server with CONTROL-C.
Watching for file changes with StatReloader
System check identified some issues:

WARNINGS:
?: (2_0.W001) Your URL pattern 'media/(?P<path>.*)' has a route that contains '(?P<', begins with a '^', or ends with a '$'. This was likely an oversight when migrating to django.urls.path().

System check identified 1 issue (0 silenced).
Not Implemented: /medicalCase/upload_picture/
[08/Mar/2024 09:42:47] "POST /medicalCase/upload_picture/ HTTP/1.1" 501 48
Not Found: /
[08/Mar/2024 09:43:08] "GET / HTTP/1.1" 404 2419
Not Found: /favicon.ico
[08/Mar/2024 09:43:08] "GET /favicon.ico HTTP/1.1" 404 2470
[08/Mar/2024 09:58:00] "GET /medicalCase/get_schedule HTTP/1.1" 301 0
[08/Mar/2024 09:58:04] "GET /medicalCase/get_schedule/ HTTP/1.1" 200 1636
/mnt/d/MyFileAtD/cancer-prediction/apps/medicalCase/api/interaction.py changed, reloading.
Performing system checks...

March 08, 2024 - 09:42:47
Django version 4.1, using settings 'cancer_prediction_backend.settings'
Starting development server at http://127.0.0.1:8000/
Quit the server with CONTROL-C.
entering upload_picture
<MultiValueDict: {}>
Watching for file changes with StatReloader
System check identified some issues:

WARNINGS:
?: (2_0.W001) Your URL pattern 'media/(?P<path>.*)' has a route that contains '(?P<', begins with a '^', or ends with a '$'. This was likely an oversight when migrating to django.urls.path().

System check identified 1 issue (0 silenced).
[08/Mar/2024 09:58:26] "GET /medicalCase/get_schedule/ HTTP/1.1" 200 1636
/mnt/d/MyFileAtD/cancer-prediction/apps/medicalCase/urls.py changed, reloading.
Performing system checks...

March 08, 2024 - 09:58:25
Django version 4.1, using settings 'cancer_prediction_backend.settings'
Starting development server at http://127.0.0.1:8000/
Quit the server with CONTROL-C.
<QueryDict: {}>
Watching for file changes with StatReloader
System check identified some issues:

WARNINGS:
?: (2_0.W001) Your URL pattern 'media/(?P<path>.*)' has a route that contains '(?P<', begins with a '^', or ends with a '$'. This was likely an oversight when migrating to django.urls.path().

System check identified 1 issue (0 silenced).
/mnt/d/MyFileAtD/cancer-prediction/apps/medicalCase/urls.py changed, reloading.
Performing system checks...

March 08, 2024 - 10:37:46
Django version 4.1, using settings 'cancer_prediction_backend.settings'
Starting development server at http://127.0.0.1:8000/
Quit the server with CONTROL-C.
Watching for file changes with StatReloader
System check identified some issues:

WARNINGS:
?: (2_0.W001) Your URL pattern 'media/(?P<path>.*)' has a route that contains '(?P<', begins with a '^', or ends with a '$'. This was likely an oversight when migrating to django.urls.path().

System check identified 1 issue (0 silenced).
Not Implemented: /medicalCase/upload_pic/
[08/Mar/2024 10:38:03] "POST /medicalCase/upload_pic/ HTTP/1.1" 501 33
Not Implemented: /medicalCase/upload_picture/
[08/Mar/2024 10:40:34] "POST /medicalCase/upload_picture/ HTTP/1.1" 501 48
/mnt/d/MyFileAtD/cancer-prediction/apps/medicalCase/views.py changed, reloading.
Performing system checks...

March 08, 2024 - 10:37:51
Django version 4.1, using settings 'cancer_prediction_backend.settings'
Starting development server at http://127.0.0.1:8000/
Quit the server with CONTROL-C.
entering upload_picture
<MultiValueDict: {}>
Watching for file changes with StatReloader
System check identified some issues:

WARNINGS:
?: (2_0.W001) Your URL pattern 'media/(?P<path>.*)' has a route that contains '(?P<', begins with a '^', or ends with a '$'. This was likely an oversight when migrating to django.urls.path().

System check identified 1 issue (0 silenced).
Not Implemented: /medicalCase/upload_pic/
[08/Mar/2024 10:42:43] "POST /medicalCase/upload_pic/ HTTP/1.1" 501 33
/mnt/d/MyFileAtD/cancer-prediction/apps/medicalCase/views.py changed, reloading.
Performing system checks...

March 08, 2024 - 10:42:36
Django version 4.1, using settings 'cancer_prediction_backend.settings'
Starting development server at http://127.0.0.1:8000/
Quit the server with CONTROL-C.
entering upload_pic
Watching for file changes with StatReloader
System check identified some issues:

WARNINGS:
?: (2_0.W001) Your URL pattern 'media/(?P<path>.*)' has a route that contains '(?P<', begins with a '^', or ends with a '$'. This was likely an oversight when migrating to django.urls.path().

System check identified 1 issue (0 silenced).
Internal Server Error: /medicalCase/upload_pic/
Traceback (most recent call last):
  File "/home/wnico/anaconda3/envs/frb5/lib/python3.10/site-packages/django/core/handlers/exception.py", line 55, in inner
    response = get_response(request)
  File "/home/wnico/anaconda3/envs/frb5/lib/python3.10/site-packages/django/core/handlers/base.py", line 197, in _get_response
    response = wrapped_callback(request, *callback_args, **callback_kwargs)
  File "/mnt/d/MyFileAtD/cancer-prediction/apps/medicalCase/views.py", line 14, in upload_pic
    if reqeust.method == 'POST':
NameError: name 'reqeust' is not defined
[08/Mar/2024 10:51:02] "POST /medicalCase/upload_pic/ HTTP/1.1" 500 64163
/mnt/d/MyFileAtD/cancer-prediction/apps/medicalCase/views.py changed, reloading.
Performing system checks...

March 08, 2024 - 10:50:08
Django version 4.1, using settings 'cancer_prediction_backend.settings'
Starting development server at http://127.0.0.1:8000/
Quit the server with CONTROL-C.
entering upload_pic
Watching for file changes with StatReloader
System check identified some issues:

WARNINGS:
?: (2_0.W001) Your URL pattern 'media/(?P<path>.*)' has a route that contains '(?P<', begins with a '^', or ends with a '$'. This was likely an oversight when migrating to django.urls.path().

System check identified 1 issue (0 silenced).
Not Implemented: /medicalCase/upload_pic/
[08/Mar/2024 10:51:13] "POST /medicalCase/upload_pic/ HTTP/1.1" 501 33
/mnt/d/MyFileAtD/cancer-prediction/apps/medicalCase/views.py changed, reloading.
Performing system checks...

March 08, 2024 - 10:51:08
Django version 4.1, using settings 'cancer_prediction_backend.settings'
Starting development server at http://127.0.0.1:8000/
Quit the server with CONTROL-C.
entering upload_pic
Watching for file changes with StatReloader
System check identified some issues:

WARNINGS:
?: (2_0.W001) Your URL pattern 'media/(?P<path>.*)' has a route that contains '(?P<', begins with a '^', or ends with a '$'. This was likely an oversight when migrating to django.urls.path().

System check identified 1 issue (0 silenced).
Not Implemented: /medicalCase/upload_pic/
[08/Mar/2024 10:51:52] "POST /medicalCase/upload_pic/ HTTP/1.1" 501 33
Not Implemented: /medicalCase/upload_pic/
[08/Mar/2024 10:51:58] "POST /medicalCase/upload_pic/ HTTP/1.1" 501 33
/mnt/d/MyFileAtD/cancer-prediction/apps/medicalCase/views.py changed, reloading.
Performing system checks...

March 08, 2024 - 10:51:51
Django version 4.1, using settings 'cancer_prediction_backend.settings'
Starting development server at http://127.0.0.1:8000/
Quit the server with CONTROL-C.
entering upload_pic
entering upload_pic
Watching for file changes with StatReloader
System check identified some issues:

WARNINGS:
?: (2_0.W001) Your URL pattern 'media/(?P<path>.*)' has a route that contains '(?P<', begins with a '^', or ends with a '$'. This was likely an oversight when migrating to django.urls.path().

System check identified 1 issue (0 silenced).
Not Implemented: /medicalCase/upload_pic/
[08/Mar/2024 10:52:18] "POST /medicalCase/upload_pic/ HTTP/1.1" 501 33
Not Implemented: /medicalCase/upload_pic/
[08/Mar/2024 10:52:50] "POST /medicalCase/upload_pic/ HTTP/1.1" 501 33
/mnt/d/MyFileAtD/cancer-prediction/apps/medicalCase/views.py changed, reloading.
Performing system checks...

March 08, 2024 - 10:52:16
Django version 4.1, using settings 'cancer_prediction_backend.settings'
Starting development server at http://127.0.0.1:8000/
Quit the server with CONTROL-C.
entering upload_pic
entering upload_pic
Watching for file changes with StatReloader
System check identified some issues:

WARNINGS:
?: (2_0.W001) Your URL pattern 'media/(?P<path>.*)' has a route that contains '(?P<', begins with a '^', or ends with a '$'. This was likely an oversight when migrating to django.urls.path().

System check identified 1 issue (0 silenced).
/mnt/d/MyFileAtD/cancer-prediction/apps/medicalCase/views.py changed, reloading.
Performing system checks...

March 08, 2024 - 10:53:25
Django version 4.1, using settings 'cancer_prediction_backend.settings'
Starting development server at http://127.0.0.1:8000/
Quit the server with CONTROL-C.
Watching for file changes with StatReloader
System check identified some issues:

WARNINGS:
?: (2_0.W001) Your URL pattern 'media/(?P<path>.*)' has a route that contains '(?P<', begins with a '^', or ends with a '$'. This was likely an oversight when migrating to django.urls.path().

System check identified 1 issue (0 silenced).
Not Implemented: /medicalCase/upload_pic/
[08/Mar/2024 10:53:28] "POST /medicalCase/upload_pic/ HTTP/1.1" 501 33
/mnt/d/MyFileAtD/cancer-prediction/apps/medicalCase/views.py changed, reloading.
Performing system checks...

March 08, 2024 - 10:53:27
Django version 4.1, using settings 'cancer_prediction_backend.settings'
Starting development server at http://127.0.0.1:8000/
Quit the server with CONTROL-C.
entering upload_pic
Watching for file changes with StatReloader
System check identified some issues:

WARNINGS:
?: (2_0.W001) Your URL pattern 'media/(?P<path>.*)' has a route that contains '(?P<', begins with a '^', or ends with a '$'. This was likely an oversight when migrating to django.urls.path().

System check identified 1 issue (0 silenced).
[08/Mar/2024 10:54:05] "GET /medicalCase/upload_pic/ HTTP/1.1" 200 29
Not Implemented: /medicalCase/upload_pic/
[08/Mar/2024 10:55:03] "POST /medicalCase/upload_pic/ HTTP/1.1" 501 33
/mnt/d/MyFileAtD/cancer-prediction/apps/medicalCase/views.py changed, reloading.
Performing system checks...

March 08, 2024 - 10:54:01
Django version 4.1, using settings 'cancer_prediction_backend.settings'
Starting development server at http://127.0.0.1:8000/
Quit the server with CONTROL-C.
entering upload_pic
get request
<tr>
    <th><label for="id_title">Title:</label></th>
    <td>
      
      <input type="text" name="title" maxlength="50" required id="id_title">
      
      
    </td>
  </tr>

  <tr>
    <th><label for="id_file">File:</label></th>
    <td>
      
      <input type="file" name="file" required id="id_file">
      
      
        
      
    </td>
  </tr>
entering upload_pic
Watching for file changes with StatReloader
System check identified some issues:

WARNINGS:
?: (2_0.W001) Your URL pattern 'media/(?P<path>.*)' has a route that contains '(?P<', begins with a '^', or ends with a '$'. This was likely an oversight when migrating to django.urls.path().

System check identified 1 issue (0 silenced).
Not Implemented: /medicalCase/upload_pic/
[08/Mar/2024 10:55:30] "POST /medicalCase/upload_pic/ HTTP/1.1" 501 33
[08/Mar/2024 10:55:52] "GET /medicalCase/upload_pic/ HTTP/1.1" 200 29
Not Implemented: /medicalCase/upload_pic/
[08/Mar/2024 10:56:27] "POST /medicalCase/upload_pic/ HTTP/1.1" 501 33
/mnt/d/MyFileAtD/cancer-prediction/apps/medicalCase/views.py changed, reloading.
Performing system checks...

March 08, 2024 - 10:55:30
Django version 4.1, using settings 'cancer_prediction_backend.settings'
Starting development server at http://127.0.0.1:8000/
Quit the server with CONTROL-C.
entering upload_pic
entering upload_pic
get request
<tr>
    <th><label for="id_title">Title:</label></th>
    <td>
      
      <input type="text" name="title" maxlength="50" required id="id_title">
      
      
    </td>
  </tr>

  <tr>
    <th><label for="id_file">File:</label></th>
    <td>
      
      <input type="file" name="file" required id="id_file">
      
      
        
      
    </td>
  </tr>
entering upload_pic
Watching for file changes with StatReloader
System check identified some issues:

WARNINGS:
?: (2_0.W001) Your URL pattern 'media/(?P<path>.*)' has a route that contains '(?P<', begins with a '^', or ends with a '$'. This was likely an oversight when migrating to django.urls.path().

System check identified 1 issue (0 silenced).
/mnt/d/MyFileAtD/cancer-prediction/apps/medicalCase/views.py changed, reloading.
Performing system checks...

March 08, 2024 - 10:56:37
Django version 4.1, using settings 'cancer_prediction_backend.settings'
Starting development server at http://127.0.0.1:8000/
Quit the server with CONTROL-C.
Watching for file changes with StatReloader
System check identified some issues:

WARNINGS:
?: (2_0.W001) Your URL pattern 'media/(?P<path>.*)' has a route that contains '(?P<', begins with a '^', or ends with a '$'. This was likely an oversight when migrating to django.urls.path().

System check identified 1 issue (0 silenced).
Internal Server Error: /medicalCase/upload_pic/
Traceback (most recent call last):
  File "/home/wnico/anaconda3/envs/frb5/lib/python3.10/site-packages/django/core/handlers/exception.py", line 55, in inner
    response = get_response(request)
  File "/home/wnico/anaconda3/envs/frb5/lib/python3.10/site-packages/django/core/handlers/base.py", line 204, in _get_response
    self.check_response(response, callback)
  File "/home/wnico/anaconda3/envs/frb5/lib/python3.10/site-packages/django/core/handlers/base.py", line 332, in check_response
    raise ValueError(
ValueError: The view apps.medicalCase.views.upload_pic didn't return an HttpResponse object. It returned None instead.
[08/Mar/2024 10:58:02] "POST /medicalCase/upload_pic/ HTTP/1.1" 500 65289
/mnt/d/MyFileAtD/cancer-prediction/apps/medicalCase/views.py changed, reloading.
Performing system checks...

March 08, 2024 - 10:57:59
Django version 4.1, using settings 'cancer_prediction_backend.settings'
Starting development server at http://127.0.0.1:8000/
Quit the server with CONTROL-C.
entering upload_pic
Watching for file changes with StatReloader
System check identified some issues:

WARNINGS:
?: (2_0.W001) Your URL pattern 'media/(?P<path>.*)' has a route that contains '(?P<', begins with a '^', or ends with a '$'. This was likely an oversight when migrating to django.urls.path().

System check identified 1 issue (0 silenced).
/mnt/d/MyFileAtD/cancer-prediction/apps/medicalCase/views.py changed, reloading.
Performing system checks...

March 08, 2024 - 10:58:09
Django version 4.1, using settings 'cancer_prediction_backend.settings'
Starting development server at http://127.0.0.1:8000/
Quit the server with CONTROL-C.
Watching for file changes with StatReloader
System check identified some issues:

WARNINGS:
?: (2_0.W001) Your URL pattern 'media/(?P<path>.*)' has a route that contains '(?P<', begins with a '^', or ends with a '$'. This was likely an oversight when migrating to django.urls.path().

System check identified 1 issue (0 silenced).
Internal Server Error: /medicalCase/upload_pic/
Traceback (most recent call last):
  File "/home/wnico/anaconda3/envs/frb5/lib/python3.10/site-packages/django/core/handlers/exception.py", line 55, in inner
    response = get_response(request)
  File "/home/wnico/anaconda3/envs/frb5/lib/python3.10/site-packages/django/core/handlers/base.py", line 204, in _get_response
    self.check_response(response, callback)
  File "/home/wnico/anaconda3/envs/frb5/lib/python3.10/site-packages/django/core/handlers/base.py", line 332, in check_response
    raise ValueError(
ValueError: The view apps.medicalCase.views.upload_pic didn't return an HttpResponse object. It returned None instead.
[08/Mar/2024 10:58:12] "POST /medicalCase/upload_pic/ HTTP/1.1" 500 65289
[08/Mar/2024 10:58:13] "GET /medicalCase/upload_pic/ HTTP/1.1" 200 29
Internal Server Error: /medicalCase/upload_pic/
Traceback (most recent call last):
  File "/home/wnico/anaconda3/envs/frb5/lib/python3.10/site-packages/django/core/handlers/exception.py", line 55, in inner
    response = get_response(request)
  File "/home/wnico/anaconda3/envs/frb5/lib/python3.10/site-packages/django/core/handlers/base.py", line 204, in _get_response
    self.check_response(response, callback)
  File "/home/wnico/anaconda3/envs/frb5/lib/python3.10/site-packages/django/core/handlers/base.py", line 332, in check_response
    raise ValueError(
ValueError: The view apps.medicalCase.views.upload_pic didn't return an HttpResponse object. It returned None instead.
[08/Mar/2024 10:58:16] "POST /medicalCase/upload_pic/ HTTP/1.1" 500 65289
/mnt/d/MyFileAtD/cancer-prediction/apps/medicalCase/views.py changed, reloading.
Performing system checks...

March 08, 2024 - 10:58:11
Django version 4.1, using settings 'cancer_prediction_backend.settings'
Starting development server at http://127.0.0.1:8000/
Quit the server with CONTROL-C.
entering upload_pic
entering upload_pic
get request
<tr>
    <th><label for="id_title">Title:</label></th>
    <td>
      
      <input type="text" name="title" maxlength="50" required id="id_title">
      
      
    </td>
  </tr>

  <tr>
    <th><label for="id_file">File:</label></th>
    <td>
      
      <input type="file" name="file" required id="id_file">
      
      
        
      
    </td>
  </tr>
entering upload_pic
Watching for file changes with StatReloader
Exception in thread django-main-thread:
Traceback (most recent call last):
  File "/home/wnico/anaconda3/envs/frb5/lib/python3.10/threading.py", line 1016, in _bootstrap_inner
    self.run()
  File "/home/wnico/anaconda3/envs/frb5/lib/python3.10/threading.py", line 953, in run
    self._target(*self._args, **self._kwargs)
  File "/home/wnico/anaconda3/envs/frb5/lib/python3.10/site-packages/django/utils/autoreload.py", line 64, in wrapper
    fn(*args, **kwargs)
  File "/home/wnico/anaconda3/envs/frb5/lib/python3.10/site-packages/django/core/management/commands/runserver.py", line 134, in inner_run
    self.check(display_num_errors=True)
  File "/home/wnico/anaconda3/envs/frb5/lib/python3.10/site-packages/django/core/management/base.py", line 475, in check
    all_issues = checks.run_checks(
  File "/home/wnico/anaconda3/envs/frb5/lib/python3.10/site-packages/django/core/checks/registry.py", line 88, in run_checks
    new_errors = check(app_configs=app_configs, databases=databases)
  File "/home/wnico/anaconda3/envs/frb5/lib/python3.10/site-packages/django/core/checks/urls.py", line 14, in check_url_config
    return check_resolver(resolver)
  File "/home/wnico/anaconda3/envs/frb5/lib/python3.10/site-packages/django/core/checks/urls.py", line 24, in check_resolver
    return check_method()
  File "/home/wnico/anaconda3/envs/frb5/lib/python3.10/site-packages/django/urls/resolvers.py", line 476, in check
    for pattern in self.url_patterns:
  File "/home/wnico/anaconda3/envs/frb5/lib/python3.10/site-packages/django/utils/functional.py", line 57, in __get__
    res = instance.__dict__[self.name] = self.func(instance)
  File "/home/wnico/anaconda3/envs/frb5/lib/python3.10/site-packages/django/urls/resolvers.py", line 690, in url_patterns
    patterns = getattr(self.urlconf_module, "urlpatterns", self.urlconf_module)
  File "/home/wnico/anaconda3/envs/frb5/lib/python3.10/site-packages/django/utils/functional.py", line 57, in __get__
    res = instance.__dict__[self.name] = self.func(instance)
  File "/home/wnico/anaconda3/envs/frb5/lib/python3.10/site-packages/django/urls/resolvers.py", line 683, in urlconf_module
    return import_module(self.urlconf_name)
  File "/home/wnico/anaconda3/envs/frb5/lib/python3.10/importlib/__init__.py", line 126, in import_module
    return _bootstrap._gcd_import(name[level:], package, level)
  File "<frozen importlib._bootstrap>", line 1050, in _gcd_import
  File "<frozen importlib._bootstrap>", line 1027, in _find_and_load
  File "<frozen importlib._bootstrap>", line 1006, in _find_and_load_unlocked
  File "<frozen importlib._bootstrap>", line 688, in _load_unlocked
  File "<frozen importlib._bootstrap_external>", line 883, in exec_module
  File "<frozen importlib._bootstrap>", line 241, in _call_with_frames_removed
  File "/mnt/d/MyFileAtD/cancer-prediction/cancer_prediction_backend/urls.py", line 26, in <module>
    path('medicalCase/', include('apps.medicalCase.urls')),
  File "/home/wnico/anaconda3/envs/frb5/lib/python3.10/site-packages/django/urls/conf.py", line 38, in include
    urlconf_module = import_module(urlconf_module)
  File "/home/wnico/anaconda3/envs/frb5/lib/python3.10/importlib/__init__.py", line 126, in import_module
    return _bootstrap._gcd_import(name[level:], package, level)
  File "<frozen importlib._bootstrap>", line 1050, in _gcd_import
  File "<frozen importlib._bootstrap>", line 1027, in _find_and_load
  File "<frozen importlib._bootstrap>", line 1006, in _find_and_load_unlocked
  File "<frozen importlib._bootstrap>", line 688, in _load_unlocked
  File "<frozen importlib._bootstrap_external>", line 883, in exec_module
  File "<frozen importlib._bootstrap>", line 241, in _call_with_frames_removed
  File "/mnt/d/MyFileAtD/cancer-prediction/apps/medicalCase/urls.py", line 3, in <module>
    from .views import upload_pic
  File "/mnt/d/MyFileAtD/cancer-prediction/apps/medicalCase/views.py", line 12, in <module>
    @csrf_exempt  # 如果您正在测试，可以临时禁用 CSRF 保护
NameError: name 'csrf_exempt' is not defined
/mnt/d/MyFileAtD/cancer-prediction/apps/medicalCase/views.py changed, reloading.
Performing system checks...

Watching for file changes with StatReloader
System check identified some issues:

WARNINGS:
?: (2_0.W001) Your URL pattern 'media/(?P<path>.*)' has a route that contains '(?P<', begins with a '^', or ends with a '$'. This was likely an oversight when migrating to django.urls.path().

System check identified 1 issue (0 silenced).
/mnt/d/MyFileAtD/cancer-prediction/apps/medicalCase/views.py changed, reloading.
Performing system checks...

March 08, 2024 - 11:00:33
Django version 4.1, using settings 'cancer_prediction_backend.settings'
Starting development server at http://127.0.0.1:8000/
Quit the server with CONTROL-C.
Watching for file changes with StatReloader
System check identified some issues:

WARNINGS:
?: (2_0.W001) Your URL pattern 'media/(?P<path>.*)' has a route that contains '(?P<', begins with a '^', or ends with a '$'. This was likely an oversight when migrating to django.urls.path().

System check identified 1 issue (0 silenced).
Bad Request: /medicalCase/upload_pic/
[08/Mar/2024 11:00:41] "POST /medicalCase/upload_pic/ HTTP/1.1" 400 86
Not Found: /medicalCaseFupload_pic/
[08/Mar/2024 11:01:28] "POST /medicalCaseFupload_pic/ HTTP/1.1" 404 2507
Not Found: /medicalCaseFupload_pic/
[08/Mar/2024 11:03:30] "POST /medicalCaseFupload_pic/ HTTP/1.1" 404 2507
Not Found: /medicalCaseFupload_pic/
[08/Mar/2024 11:03:32] "POST /medicalCaseFupload_pic/ HTTP/1.1" 404 2507
Bad Request: /medicalCase/upload_pic/
[08/Mar/2024 11:03:44] "POST /medicalCase/upload_pic/ HTTP/1.1" 400 49
Bad Request: /medicalCase/upload_pic/
[08/Mar/2024 11:03:57] "POST /medicalCase/upload_pic/ HTTP/1.1" 400 49
/mnt/d/MyFileAtD/cancer-prediction/apps/medicalCase/views.py changed, reloading.
Performing system checks...

March 08, 2024 - 11:00:38
Django version 4.1, using settings 'cancer_prediction_backend.settings'
Starting development server at http://127.0.0.1:8000/
Quit the server with CONTROL-C.
Watching for file changes with StatReloader
System check identified some issues:

WARNINGS:
?: (2_0.W001) Your URL pattern 'media/(?P<path>.*)' has a route that contains '(?P<', begins with a '^', or ends with a '$'. This was likely an oversight when migrating to django.urls.path().

System check identified 1 issue (0 silenced).
Bad Request: /medicalCase/upload_pic/
[08/Mar/2024 11:07:02] "POST /medicalCase/upload_pic/ HTTP/1.1" 400 49
Bad Request: /medicalCase/upload_pic/
[08/Mar/2024 11:07:03] "POST /medicalCase/upload_pic/ HTTP/1.1" 400 49
[08/Mar/2024 11:07:56] "POST /medicalCase/upload_pic/ HTTP/1.1" 200 41
/mnt/d/MyFileAtD/cancer-prediction/apps/medicalCase/views.py changed, reloading.
Performing system checks...

March 08, 2024 - 11:07:00
Django version 4.1, using settings 'cancer_prediction_backend.settings'
Starting development server at http://127.0.0.1:8000/
Quit the server with CONTROL-C.
Watching for file changes with StatReloader
System check identified some issues:

WARNINGS:
?: (2_0.W001) Your URL pattern 'media/(?P<path>.*)' has a route that contains '(?P<', begins with a '^', or ends with a '$'. This was likely an oversight when migrating to django.urls.path().

System check identified 1 issue (0 silenced).
[08/Mar/2024 11:16:03] "GET /admin/ HTTP/1.1" 200 5803
[08/Mar/2024 11:16:20] "GET /admin/medicalCase/case/ HTTP/1.1" 200 7080
[08/Mar/2024 11:16:20] "GET /admin/jsi18n/ HTTP/1.1" 200 3343
[08/Mar/2024 11:16:21] "GET /admin/medicalCase/case/1/change/ HTTP/1.1" 200 7854
[08/Mar/2024 11:16:21] "GET /admin/jsi18n/ HTTP/1.1" 200 3343
[08/Mar/2024 11:16:22] "GET /admin/medicalCase/image/ HTTP/1.1" 200 7091
[08/Mar/2024 11:16:22] "GET /admin/jsi18n/ HTTP/1.1" 200 3343
[08/Mar/2024 11:16:23] "GET /admin/medicalCase/image/1/change/ HTTP/1.1" 200 8401
[08/Mar/2024 11:16:23] "GET /admin/jsi18n/ HTTP/1.1" 200 3343
Not Found: /images/下载.jfif
[08/Mar/2024 11:16:24] "GET /images/%E4%B8%8B%E8%BD%BD.jfif HTTP/1.1" 404 2503
Not Found: /media/images/下载.jfif
[08/Mar/2024 11:16:28] "GET /media/images/%E4%B8%8B%E8%BD%BD.jfif HTTP/1.1" 404 2521
/mnt/d/MyFileAtD/cancer-prediction/cancer_prediction_backend/urls.py changed, reloading.
Performing system checks...

March 08, 2024 - 11:14:29
Django version 4.1, using settings 'cancer_prediction_backend.settings'
Starting development server at http://127.0.0.1:8000/
Quit the server with CONTROL-C.
Watching for file changes with StatReloader
Exception in thread django-main-thread:
Traceback (most recent call last):
  File "/home/wnico/anaconda3/envs/frb5/lib/python3.10/threading.py", line 1016, in _bootstrap_inner
    self.run()
  File "/home/wnico/anaconda3/envs/frb5/lib/python3.10/threading.py", line 953, in run
    self._target(*self._args, **self._kwargs)
  File "/home/wnico/anaconda3/envs/frb5/lib/python3.10/site-packages/django/utils/autoreload.py", line 64, in wrapper
    fn(*args, **kwargs)
  File "/home/wnico/anaconda3/envs/frb5/lib/python3.10/site-packages/django/core/management/commands/runserver.py", line 134, in inner_run
    self.check(display_num_errors=True)
  File "/home/wnico/anaconda3/envs/frb5/lib/python3.10/site-packages/django/core/management/base.py", line 475, in check
    all_issues = checks.run_checks(
  File "/home/wnico/anaconda3/envs/frb5/lib/python3.10/site-packages/django/core/checks/registry.py", line 88, in run_checks
    new_errors = check(app_configs=app_configs, databases=databases)
  File "/home/wnico/anaconda3/envs/frb5/lib/python3.10/site-packages/django/core/checks/urls.py", line 14, in check_url_config
    return check_resolver(resolver)
  File "/home/wnico/anaconda3/envs/frb5/lib/python3.10/site-packages/django/core/checks/urls.py", line 24, in check_resolver
    return check_method()
  File "/home/wnico/anaconda3/envs/frb5/lib/python3.10/site-packages/django/urls/resolvers.py", line 476, in check
    for pattern in self.url_patterns:
  File "/home/wnico/anaconda3/envs/frb5/lib/python3.10/site-packages/django/utils/functional.py", line 57, in __get__
    res = instance.__dict__[self.name] = self.func(instance)
  File "/home/wnico/anaconda3/envs/frb5/lib/python3.10/site-packages/django/urls/resolvers.py", line 690, in url_patterns
    patterns = getattr(self.urlconf_module, "urlpatterns", self.urlconf_module)
  File "/home/wnico/anaconda3/envs/frb5/lib/python3.10/site-packages/django/utils/functional.py", line 57, in __get__
    res = instance.__dict__[self.name] = self.func(instance)
  File "/home/wnico/anaconda3/envs/frb5/lib/python3.10/site-packages/django/urls/resolvers.py", line 683, in urlconf_module
    return import_module(self.urlconf_name)
  File "/home/wnico/anaconda3/envs/frb5/lib/python3.10/importlib/__init__.py", line 126, in import_module
    return _bootstrap._gcd_import(name[level:], package, level)
  File "<frozen importlib._bootstrap>", line 1050, in _gcd_import
  File "<frozen importlib._bootstrap>", line 1027, in _find_and_load
  File "<frozen importlib._bootstrap>", line 1006, in _find_and_load_unlocked
  File "<frozen importlib._bootstrap>", line 688, in _load_unlocked
  File "<frozen importlib._bootstrap_external>", line 883, in exec_module
  File "<frozen importlib._bootstrap>", line 241, in _call_with_frames_removed
  File "/mnt/d/MyFileAtD/cancer-prediction/cancer_prediction_backend/urls.py", line 27, in <module>
    urlpatterns(r'media/(?P<path>.*)',serve,{'document_root':settings.MEDIA_ROOT})
NameError: name 'urlpatterns' is not defined
/mnt/d/MyFileAtD/cancer-prediction/cancer_prediction_backend/urls.py changed, reloading.
Performing system checks...

Watching for file changes with StatReloader
Exception in thread django-main-thread:
Traceback (most recent call last):
  File "/home/wnico/anaconda3/envs/frb5/lib/python3.10/threading.py", line 1016, in _bootstrap_inner
    self.run()
  File "/home/wnico/anaconda3/envs/frb5/lib/python3.10/threading.py", line 953, in run
    self._target(*self._args, **self._kwargs)
  File "/home/wnico/anaconda3/envs/frb5/lib/python3.10/site-packages/django/utils/autoreload.py", line 64, in wrapper
    fn(*args, **kwargs)
  File "/home/wnico/anaconda3/envs/frb5/lib/python3.10/site-packages/django/core/management/commands/runserver.py", line 134, in inner_run
    self.check(display_num_errors=True)
  File "/home/wnico/anaconda3/envs/frb5/lib/python3.10/site-packages/django/core/management/base.py", line 475, in check
    all_issues = checks.run_checks(
  File "/home/wnico/anaconda3/envs/frb5/lib/python3.10/site-packages/django/core/checks/registry.py", line 88, in run_checks
    new_errors = check(app_configs=app_configs, databases=databases)
  File "/home/wnico/anaconda3/envs/frb5/lib/python3.10/site-packages/django/core/checks/urls.py", line 14, in check_url_config
    return check_resolver(resolver)
  File "/home/wnico/anaconda3/envs/frb5/lib/python3.10/site-packages/django/core/checks/urls.py", line 24, in check_resolver
    return check_method()
  File "/home/wnico/anaconda3/envs/frb5/lib/python3.10/site-packages/django/urls/resolvers.py", line 476, in check
    for pattern in self.url_patterns:
  File "/home/wnico/anaconda3/envs/frb5/lib/python3.10/site-packages/django/utils/functional.py", line 57, in __get__
    res = instance.__dict__[self.name] = self.func(instance)
  File "/home/wnico/anaconda3/envs/frb5/lib/python3.10/site-packages/django/urls/resolvers.py", line 690, in url_patterns
    patterns = getattr(self.urlconf_module, "urlpatterns", self.urlconf_module)
  File "/home/wnico/anaconda3/envs/frb5/lib/python3.10/site-packages/django/utils/functional.py", line 57, in __get__
    res = instance.__dict__[self.name] = self.func(instance)
  File "/home/wnico/anaconda3/envs/frb5/lib/python3.10/site-packages/django/urls/resolvers.py", line 683, in urlconf_module
    return import_module(self.urlconf_name)
  File "/home/wnico/anaconda3/envs/frb5/lib/python3.10/importlib/__init__.py", line 126, in import_module
    return _bootstrap._gcd_import(name[level:], package, level)
  File "<frozen importlib._bootstrap>", line 1050, in _gcd_import
  File "<frozen importlib._bootstrap>", line 1027, in _find_and_load
  File "<frozen importlib._bootstrap>", line 1006, in _find_and_load_unlocked
  File "<frozen importlib._bootstrap>", line 688, in _load_unlocked
  File "<frozen importlib._bootstrap_external>", line 883, in exec_module
  File "<frozen importlib._bootstrap>", line 241, in _call_with_frames_removed
  File "/mnt/d/MyFileAtD/cancer-prediction/cancer_prediction_backend/urls.py", line 27, in <module>
    url(r'media/(?P<path>.*)',serve,{'document_root':settings.MEDIA_ROOT})
NameError: name 'url' is not defined
/mnt/d/MyFileAtD/cancer-prediction/cancer_prediction_backend/urls.py changed, reloading.
Performing system checks...

Watching for file changes with StatReloader
Exception in thread django-main-thread:
Traceback (most recent call last):
  File "/home/wnico/anaconda3/envs/frb5/lib/python3.10/threading.py", line 1016, in _bootstrap_inner
    self.run()
  File "/home/wnico/anaconda3/envs/frb5/lib/python3.10/threading.py", line 953, in run
    self._target(*self._args, **self._kwargs)
  File "/home/wnico/anaconda3/envs/frb5/lib/python3.10/site-packages/django/utils/autoreload.py", line 64, in wrapper
    fn(*args, **kwargs)
  File "/home/wnico/anaconda3/envs/frb5/lib/python3.10/site-packages/django/core/management/commands/runserver.py", line 134, in inner_run
    self.check(display_num_errors=True)
  File "/home/wnico/anaconda3/envs/frb5/lib/python3.10/site-packages/django/core/management/base.py", line 475, in check
    all_issues = checks.run_checks(
  File "/home/wnico/anaconda3/envs/frb5/lib/python3.10/site-packages/django/core/checks/registry.py", line 88, in run_checks
    new_errors = check(app_configs=app_configs, databases=databases)
  File "/home/wnico/anaconda3/envs/frb5/lib/python3.10/site-packages/django/core/checks/urls.py", line 14, in check_url_config
    return check_resolver(resolver)
  File "/home/wnico/anaconda3/envs/frb5/lib/python3.10/site-packages/django/core/checks/urls.py", line 24, in check_resolver
    return check_method()
  File "/home/wnico/anaconda3/envs/frb5/lib/python3.10/site-packages/django/urls/resolvers.py", line 476, in check
    for pattern in self.url_patterns:
  File "/home/wnico/anaconda3/envs/frb5/lib/python3.10/site-packages/django/utils/functional.py", line 57, in __get__
    res = instance.__dict__[self.name] = self.func(instance)
  File "/home/wnico/anaconda3/envs/frb5/lib/python3.10/site-packages/django/urls/resolvers.py", line 690, in url_patterns
    patterns = getattr(self.urlconf_module, "urlpatterns", self.urlconf_module)
  File "/home/wnico/anaconda3/envs/frb5/lib/python3.10/site-packages/django/utils/functional.py", line 57, in __get__
    res = instance.__dict__[self.name] = self.func(instance)
  File "/home/wnico/anaconda3/envs/frb5/lib/python3.10/site-packages/django/urls/resolvers.py", line 683, in urlconf_module
    return import_module(self.urlconf_name)
  File "/home/wnico/anaconda3/envs/frb5/lib/python3.10/importlib/__init__.py", line 126, in import_module
    return _bootstrap._gcd_import(name[level:], package, level)
  File "<frozen importlib._bootstrap>", line 1050, in _gcd_import
  File "<frozen importlib._bootstrap>", line 1027, in _find_and_load
  File "<frozen importlib._bootstrap>", line 1006, in _find_and_load_unlocked
  File "<frozen importlib._bootstrap>", line 688, in _load_unlocked
  File "<frozen importlib._bootstrap_external>", line 883, in exec_module
  File "<frozen importlib._bootstrap>", line 241, in _call_with_frames_removed
  File "/mnt/d/MyFileAtD/cancer-prediction/cancer_prediction_backend/urls.py", line 18, in <module>
    from django.conf.urls import url
ImportError: cannot import name 'url' from 'django.conf.urls' (/home/wnico/anaconda3/envs/frb5/lib/python3.10/site-packages/django/conf/urls/__init__.py)
/mnt/d/MyFileAtD/cancer-prediction/cancer_prediction_backend/urls.py changed, reloading.
Performing system checks...

Watching for file changes with StatReloader
Exception in thread django-main-thread:
Traceback (most recent call last):
  File "/home/wnico/anaconda3/envs/frb5/lib/python3.10/threading.py", line 1016, in _bootstrap_inner
    self.run()
  File "/home/wnico/anaconda3/envs/frb5/lib/python3.10/threading.py", line 953, in run
    self._target(*self._args, **self._kwargs)
  File "/home/wnico/anaconda3/envs/frb5/lib/python3.10/site-packages/django/utils/autoreload.py", line 64, in wrapper
    fn(*args, **kwargs)
  File "/home/wnico/anaconda3/envs/frb5/lib/python3.10/site-packages/django/core/management/commands/runserver.py", line 134, in inner_run
    self.check(display_num_errors=True)
  File "/home/wnico/anaconda3/envs/frb5/lib/python3.10/site-packages/django/core/management/base.py", line 475, in check
    all_issues = checks.run_checks(
  File "/home/wnico/anaconda3/envs/frb5/lib/python3.10/site-packages/django/core/checks/registry.py", line 88, in run_checks
    new_errors = check(app_configs=app_configs, databases=databases)
  File "/home/wnico/anaconda3/envs/frb5/lib/python3.10/site-packages/django/core/checks/urls.py", line 14, in check_url_config
    return check_resolver(resolver)
  File "/home/wnico/anaconda3/envs/frb5/lib/python3.10/site-packages/django/core/checks/urls.py", line 24, in check_resolver
    return check_method()
  File "/home/wnico/anaconda3/envs/frb5/lib/python3.10/site-packages/django/urls/resolvers.py", line 476, in check
    for pattern in self.url_patterns:
  File "/home/wnico/anaconda3/envs/frb5/lib/python3.10/site-packages/django/utils/functional.py", line 57, in __get__
    res = instance.__dict__[self.name] = self.func(instance)
  File "/home/wnico/anaconda3/envs/frb5/lib/python3.10/site-packages/django/urls/resolvers.py", line 690, in url_patterns
    patterns = getattr(self.urlconf_module, "urlpatterns", self.urlconf_module)
  File "/home/wnico/anaconda3/envs/frb5/lib/python3.10/site-packages/django/utils/functional.py", line 57, in __get__
    res = instance.__dict__[self.name] = self.func(instance)
  File "/home/wnico/anaconda3/envs/frb5/lib/python3.10/site-packages/django/urls/resolvers.py", line 683, in urlconf_module
    return import_module(self.urlconf_name)
  File "/home/wnico/anaconda3/envs/frb5/lib/python3.10/importlib/__init__.py", line 126, in import_module
    return _bootstrap._gcd_import(name[level:], package, level)
  File "<frozen importlib._bootstrap>", line 1050, in _gcd_import
  File "<frozen importlib._bootstrap>", line 1027, in _find_and_load
  File "<frozen importlib._bootstrap>", line 1006, in _find_and_load_unlocked
  File "<frozen importlib._bootstrap>", line 688, in _load_unlocked
  File "<frozen importlib._bootstrap_external>", line 883, in exec_module
  File "<frozen importlib._bootstrap>", line 241, in _call_with_frames_removed
  File "/mnt/d/MyFileAtD/cancer-prediction/cancer_prediction_backend/urls.py", line 26, in <module>
    url(r'media/(?P<path>.*)',serve,{'document_root':settings.MEDIA_ROOT})
NameError: name 'url' is not defined
/mnt/d/MyFileAtD/cancer-prediction/cancer_prediction_backend/urls.py changed, reloading.
Performing system checks...

Watching for file changes with StatReloader
[08/Mar/2024 11:35:42] "GET /media/images/%E4%B8%8B%E8%BD%BD.jfif HTTP/1.1" 200 8514
[08/Mar/2024 11:44:36] "GET /media/images/%E4%B8%8B%E8%BD%BD.jfif HTTP/1.1" 304 0
/mnt/d/MyFileAtD/cancer-prediction/apps/medicalCase/urls.py changed, reloading.
Performing system checks...

System check identified no issues (0 silenced).
March 08, 2024 - 11:35:24
Django version 4.1, using settings 'cancer_prediction_backend.settings'
Starting development server at http://127.0.0.1:8000/
Quit the server with CONTROL-C.
Watching for file changes with StatReloader
/mnt/d/MyFileAtD/cancer-prediction/apps/medicalCase/views.py changed, reloading.
Performing system checks...

System check identified no issues (0 silenced).
March 08, 2024 - 11:56:50
Django version 4.1, using settings 'cancer_prediction_backend.settings'
Starting development server at http://127.0.0.1:8000/
Quit the server with CONTROL-C.
Watching for file changes with StatReloader
/mnt/d/MyFileAtD/cancer-prediction/apps/medicalCase/views.py changed, reloading.
Performing system checks...

System check identified no issues (0 silenced).
March 08, 2024 - 11:59:38
Django version 4.1, using settings 'cancer_prediction_backend.settings'
Starting development server at http://127.0.0.1:8000/
Quit the server with CONTROL-C.
Watching for file changes with StatReloader
/mnt/d/MyFileAtD/cancer-prediction/apps/medicalCase/views.py changed, reloading.
Performing system checks...

System check identified no issues (0 silenced).
March 08, 2024 - 11:59:45
Django version 4.1, using settings 'cancer_prediction_backend.settings'
Starting development server at http://127.0.0.1:8000/
Quit the server with CONTROL-C.
Watching for file changes with StatReloader
/mnt/d/MyFileAtD/cancer-prediction/apps/medicalCase/views.py changed, reloading.
Performing system checks...

System check identified no issues (0 silenced).
March 08, 2024 - 11:59:53
Django version 4.1, using settings 'cancer_prediction_backend.settings'
Starting development server at http://127.0.0.1:8000/
Quit the server with CONTROL-C.
Watching for file changes with StatReloader
/mnt/d/MyFileAtD/cancer-prediction/cancer_prediction_backend/urls.py changed, reloading.
Performing system checks...

System check identified no issues (0 silenced).
March 08, 2024 - 12:00:26
Django version 4.1, using settings 'cancer_prediction_backend.settings'
Starting development server at http://127.0.0.1:8000/
Quit the server with CONTROL-C.
Watching for file changes with StatReloader
Exception in thread django-main-thread:
Traceback (most recent call last):
  File "/home/wnico/anaconda3/envs/frb5/lib/python3.10/threading.py", line 1016, in _bootstrap_inner
    self.run()
  File "/home/wnico/anaconda3/envs/frb5/lib/python3.10/threading.py", line 953, in run
    self._target(*self._args, **self._kwargs)
  File "/home/wnico/anaconda3/envs/frb5/lib/python3.10/site-packages/django/utils/autoreload.py", line 64, in wrapper
    fn(*args, **kwargs)
  File "/home/wnico/anaconda3/envs/frb5/lib/python3.10/site-packages/django/core/management/commands/runserver.py", line 134, in inner_run
    self.check(display_num_errors=True)
  File "/home/wnico/anaconda3/envs/frb5/lib/python3.10/site-packages/django/core/management/base.py", line 475, in check
    all_issues = checks.run_checks(
  File "/home/wnico/anaconda3/envs/frb5/lib/python3.10/site-packages/django/core/checks/registry.py", line 88, in run_checks
    new_errors = check(app_configs=app_configs, databases=databases)
  File "/home/wnico/anaconda3/envs/frb5/lib/python3.10/site-packages/django/core/checks/urls.py", line 14, in check_url_config
    return check_resolver(resolver)
  File "/home/wnico/anaconda3/envs/frb5/lib/python3.10/site-packages/django/core/checks/urls.py", line 24, in check_resolver
    return check_method()
  File "/home/wnico/anaconda3/envs/frb5/lib/python3.10/site-packages/django/urls/resolvers.py", line 476, in check
    for pattern in self.url_patterns:
  File "/home/wnico/anaconda3/envs/frb5/lib/python3.10/site-packages/django/utils/functional.py", line 57, in __get__
    res = instance.__dict__[self.name] = self.func(instance)
  File "/home/wnico/anaconda3/envs/frb5/lib/python3.10/site-packages/django/urls/resolvers.py", line 690, in url_patterns
    patterns = getattr(self.urlconf_module, "urlpatterns", self.urlconf_module)
  File "/home/wnico/anaconda3/envs/frb5/lib/python3.10/site-packages/django/utils/functional.py", line 57, in __get__
    res = instance.__dict__[self.name] = self.func(instance)
  File "/home/wnico/anaconda3/envs/frb5/lib/python3.10/site-packages/django/urls/resolvers.py", line 683, in urlconf_module
    return import_module(self.urlconf_name)
  File "/home/wnico/anaconda3/envs/frb5/lib/python3.10/importlib/__init__.py", line 126, in import_module
    return _bootstrap._gcd_import(name[level:], package, level)
  File "<frozen importlib._bootstrap>", line 1050, in _gcd_import
  File "<frozen importlib._bootstrap>", line 1027, in _find_and_load
  File "<frozen importlib._bootstrap>", line 1006, in _find_and_load_unlocked
  File "<frozen importlib._bootstrap>", line 688, in _load_unlocked
  File "<frozen importlib._bootstrap_external>", line 879, in exec_module
  File "<frozen importlib._bootstrap_external>", line 1017, in get_code
  File "<frozen importlib._bootstrap_external>", line 947, in source_to_code
  File "<frozen importlib._bootstrap>", line 241, in _call_with_frames_removed
  File "/mnt/d/MyFileAtD/cancer-prediction/cancer_prediction_backend/urls.py", line 27
    re_path(r'media/(?P<path>.*)',serve,{'document_root':settings.MEDIA_ROOT})
    ^^^^^^^^^^^^^^^^^^^^^^^^^^^^^^^^^^^^^^^^^^^^^^^^^^^^^^^^^^^^^^^^^^^^^^^^^^
SyntaxError: invalid syntax. Perhaps you forgot a comma?
/mnt/d/MyFileAtD/cancer-prediction/cancer_prediction_backend/urls.py changed, reloading.
Performing system checks...

Watching for file changes with StatReloader
Not Found: /images/下载.jfif
[08/Mar/2024 12:01:39] "GET /images/%E4%B8%8B%E8%BD%BD.jfif HTTP/1.1" 404 2626
/mnt/d/MyFileAtD/cancer-prediction/cancer_prediction_backend/urls.py changed, reloading.
Performing system checks...

System check identified no issues (0 silenced).
March 08, 2024 - 12:01:28
Django version 4.1, using settings 'cancer_prediction_backend.settings'
Starting development server at http://127.0.0.1:8000/
Quit the server with CONTROL-C.
Watching for file changes with StatReloader
Not Found: /images/下载.jfif
[08/Mar/2024 12:01:51] "GET /images/%E4%B8%8B%E8%BD%BD.jfif HTTP/1.1" 404 2626
/mnt/d/MyFileAtD/cancer-prediction/cancer_prediction_backend/urls.py changed, reloading.
Performing system checks...

System check identified no issues (0 silenced).
March 08, 2024 - 12:01:50
Django version 4.1, using settings 'cancer_prediction_backend.settings'
Starting development server at http://127.0.0.1:8000/
Quit the server with CONTROL-C.
Watching for file changes with StatReloader
Not Found: /images/下载.jfif
[08/Mar/2024 12:02:08] "GET /images/%E4%B8%8B%E8%BD%BD.jfif HTTP/1.1" 404 2627
Not Found: /images/下载.jfif
[08/Mar/2024 12:02:11] "GET /images/%E4%B8%8B%E8%BD%BD.jfif HTTP/1.1" 404 2627
/mnt/d/MyFileAtD/cancer-prediction/cancer_prediction_backend/urls.py changed, reloading.
Performing system checks...

System check identified no issues (0 silenced).
March 08, 2024 - 12:02:07
Django version 4.1, using settings 'cancer_prediction_backend.settings'
Starting development server at http://127.0.0.1:8000/
Quit the server with CONTROL-C.
Watching for file changes with StatReloader
[08/Mar/2024 12:02:19] "GET /images/%E4%B8%8B%E8%BD%BD.jfif HTTP/1.1" 302 0
Not Found: /media/image/下载.jfif
[08/Mar/2024 12:02:19] "GET /media/image/%E4%B8%8B%E8%BD%BD.jfif HTTP/1.1" 404 2726
Not Found: /media/image/下载.jfif
[08/Mar/2024 12:02:21] "GET /media/image/%E4%B8%8B%E8%BD%BD.jfif HTTP/1.1" 404 2726
/mnt/d/MyFileAtD/cancer-prediction/cancer_prediction_backend/urls.py changed, reloading.
Performing system checks...

System check identified no issues (0 silenced).
March 08, 2024 - 12:02:18
Django version 4.1, using settings 'cancer_prediction_backend.settings'
Starting development server at http://127.0.0.1:8000/
Quit the server with CONTROL-C.
Watching for file changes with StatReloader
Not Found: /media/image/下载.jfif
[08/Mar/2024 12:02:32] "GET /media/image/%E4%B8%8B%E8%BD%BD.jfif HTTP/1.1" 404 2726
/mnt/d/MyFileAtD/cancer-prediction/cancer_prediction_backend/urls.py changed, reloading.
Performing system checks...

System check identified no issues (0 silenced).
March 08, 2024 - 12:02:32
Django version 4.1, using settings 'cancer_prediction_backend.settings'
Starting development server at http://127.0.0.1:8000/
Quit the server with CONTROL-C.
Watching for file changes with StatReloader
[08/Mar/2024 12:02:44] "GET /images/%E4%B8%8B%E8%BD%BD.jfif HTTP/1.1" 302 0
[08/Mar/2024 12:02:51] "GET /admin/ HTTP/1.1" 200 5803
[08/Mar/2024 12:02:52] "GET /admin/medicalCase/image/ HTTP/1.1" 200 7091
[08/Mar/2024 12:02:52] "GET /admin/jsi18n/ HTTP/1.1" 200 3343
[08/Mar/2024 12:02:53] "GET /admin/medicalCase/image/1/change/ HTTP/1.1" 200 8401
[08/Mar/2024 12:02:53] "GET /admin/jsi18n/ HTTP/1.1" 200 3343
[08/Mar/2024 12:02:54] "GET /images/%E4%B8%8B%E8%BD%BD.jfif HTTP/1.1" 302 0
[08/Mar/2024 12:02:55] "GET /admin/medicalCase/image/1/change/ HTTP/1.1" 200 8401
[08/Mar/2024 12:02:56] "GET /images/%E4%B8%8B%E8%BD%BD.jfif HTTP/1.1" 302 0
[08/Mar/2024 12:02:57] "GET /admin/medicalCase/image/1/change/ HTTP/1.1" 200 8401
/mnt/d/MyFileAtD/cancer-prediction/cancer_prediction_backend/urls.py changed, reloading.
Performing system checks...

System check identified no issues (0 silenced).
March 08, 2024 - 12:02:37
Django version 4.1, using settings 'cancer_prediction_backend.settings'
Starting development server at http://127.0.0.1:8000/
Quit the server with CONTROL-C.
Watching for file changes with StatReloader
/mnt/d/MyFileAtD/cancer-prediction/cancer_prediction_backend/urls.py changed, reloading.
Performing system checks...

System check identified no issues (0 silenced).
March 08, 2024 - 12:03:31
Django version 4.1, using settings 'cancer_prediction_backend.settings'
Starting development server at http://127.0.0.1:8000/
Quit the server with CONTROL-C.
Watching for file changes with StatReloader
/mnt/d/MyFileAtD/cancer-prediction/cancer_prediction_backend/urls.py changed, reloading.
Performing system checks...

System check identified no issues (0 silenced).
March 08, 2024 - 12:03:35
Django version 4.1, using settings 'cancer_prediction_backend.settings'
Starting development server at http://127.0.0.1:8000/
Quit the server with CONTROL-C.
Watching for file changes with StatReloader
Not Found: /images/下载.jfif
[08/Mar/2024 12:03:38] "GET /images/%E4%B8%8B%E8%BD%BD.jfif HTTP/1.1" 404 2836
/mnt/d/MyFileAtD/cancer-prediction/cancer_prediction_backend/urls.py changed, reloading.
Performing system checks...

System check identified no issues (0 silenced).
March 08, 2024 - 12:03:37
Django version 4.1, using settings 'cancer_prediction_backend.settings'
Starting development server at http://127.0.0.1:8000/
Quit the server with CONTROL-C.
Watching for file changes with StatReloader
[08/Mar/2024 12:03:44] "GET /images/%E4%B8%8B%E8%BD%BD.jfif HTTP/1.1" 200 8514
[08/Mar/2024 12:03:45] "GET /admin/medicalCase/image/1/change/ HTTP/1.1" 200 8401
[08/Mar/2024 12:03:47] "GET /admin/medicalCase/image/1/change/ HTTP/1.1" 200 8401
[08/Mar/2024 12:03:49] "GET /admin/medicalCase/image/1/change/ HTTP/1.1" 200 8401
Bad Request: /medicalCase/upload_pic/
[08/Mar/2024 12:04:20] "POST /medicalCase/upload_pic/ HTTP/1.1" 400 95
[08/Mar/2024 12:04:36] "POST /medicalCase/upload_pic/ HTTP/1.1" 200 41
/mnt/d/MyFileAtD/cancer-prediction/apps/medicalCase/views.py changed, reloading.
Performing system checks...

System check identified no issues (0 silenced).
March 08, 2024 - 12:03:43
Django version 4.1, using settings 'cancer_prediction_backend.settings'
Starting development server at http://127.0.0.1:8000/
Quit the server with CONTROL-C.
Watching for file changes with StatReloader
/mnt/d/MyFileAtD/cancer-prediction/apps/medicalCase/views.py changed, reloading.
Performing system checks...

System check identified no issues (0 silenced).
March 08, 2024 - 12:05:37
Django version 4.1, using settings 'cancer_prediction_backend.settings'
Starting development server at http://127.0.0.1:8000/
Quit the server with CONTROL-C.
Watching for file changes with StatReloader
[08/Mar/2024 12:06:06] "POST /medicalCase/upload_pic/ HTTP/1.1" 200 41
[08/Mar/2024 12:06:29] "GET /images/test.jpg HTTP/1.1" 200 9016
/mnt/d/MyFileAtD/cancer-prediction/apps/medicalCase/views.py changed, reloading.
Performing system checks...

System check identified no issues (0 silenced).
March 08, 2024 - 12:06:03
Django version 4.1, using settings 'cancer_prediction_backend.settings'
Starting development server at http://127.0.0.1:8000/
Quit the server with CONTROL-C.
Watching for file changes with StatReloader
/mnt/d/MyFileAtD/cancer-prediction/apps/medicalCase/views.py changed, reloading.
Performing system checks...

System check identified no issues (0 silenced).
March 08, 2024 - 12:11:06
Django version 4.1, using settings 'cancer_prediction_backend.settings'
Starting development server at http://127.0.0.1:8000/
Quit the server with CONTROL-C.
Watching for file changes with StatReloader
/mnt/d/MyFileAtD/cancer-prediction/apps/medicalCase/views.py changed, reloading.
Performing system checks...

System check identified no issues (0 silenced).
March 08, 2024 - 12:11:22
Django version 4.1, using settings 'cancer_prediction_backend.settings'
Starting development server at http://127.0.0.1:8000/
Quit the server with CONTROL-C.
Watching for file changes with StatReloader
/mnt/d/MyFileAtD/cancer-prediction/apps/medicalCase/views.py changed, reloading.
Performing system checks...

System check identified no issues (0 silenced).
March 08, 2024 - 12:11:28
Django version 4.1, using settings 'cancer_prediction_backend.settings'
Starting development server at http://127.0.0.1:8000/
Quit the server with CONTROL-C.
Watching for file changes with StatReloader
/mnt/d/MyFileAtD/cancer-prediction/apps/medicalCase/views.py changed, reloading.
Performing system checks...

System check identified no issues (0 silenced).
March 08, 2024 - 12:11:34
Django version 4.1, using settings 'cancer_prediction_backend.settings'
Starting development server at http://127.0.0.1:8000/
Quit the server with CONTROL-C.
Watching for file changes with StatReloader
/mnt/d/MyFileAtD/cancer-prediction/apps/medicalCase/views.py changed, reloading.
Performing system checks...

System check identified no issues (0 silenced).
March 08, 2024 - 12:11:42
Django version 4.1, using settings 'cancer_prediction_backend.settings'
Starting development server at http://127.0.0.1:8000/
Quit the server with CONTROL-C.
Watching for file changes with StatReloader
/mnt/d/MyFileAtD/cancer-prediction/apps/medicalCase/views.py changed, reloading.
Performing system checks...

System check identified no issues (0 silenced).
March 08, 2024 - 12:11:51
Django version 4.1, using settings 'cancer_prediction_backend.settings'
Starting development server at http://127.0.0.1:8000/
Quit the server with CONTROL-C.
Watching for file changes with StatReloader
Internal Server Error: /medicalCase/upload_pic/
Traceback (most recent call last):
  File "/home/wnico/anaconda3/envs/frb5/lib/python3.10/site-packages/django/db/backends/utils.py", line 89, in _execute
    return self.cursor.execute(sql, params)
  File "/home/wnico/anaconda3/envs/frb5/lib/python3.10/site-packages/django/db/backends/sqlite3/base.py", line 357, in execute
    return Database.Cursor.execute(self, query, params)
sqlite3.IntegrityError: NOT NULL constraint failed: medicalCase_image.case_id

The above exception was the direct cause of the following exception:

Traceback (most recent call last):
  File "/home/wnico/anaconda3/envs/frb5/lib/python3.10/site-packages/django/core/handlers/exception.py", line 55, in inner
    response = get_response(request)
  File "/home/wnico/anaconda3/envs/frb5/lib/python3.10/site-packages/django/core/handlers/base.py", line 197, in _get_response
    response = wrapped_callback(request, *callback_args, **callback_kwargs)
  File "/home/wnico/anaconda3/envs/frb5/lib/python3.10/site-packages/django/views/decorators/csrf.py", line 54, in wrapped_view
    return view_func(*args, **kwargs)
  File "/mnt/d/MyFileAtD/cancer-prediction/apps/medicalCase/views.py", line 26, in upload_pic
    Image.objects.create(image=saved_pic)
  File "/home/wnico/anaconda3/envs/frb5/lib/python3.10/site-packages/django/db/models/manager.py", line 85, in manager_method
    return getattr(self.get_queryset(), name)(*args, **kwargs)
  File "/home/wnico/anaconda3/envs/frb5/lib/python3.10/site-packages/django/db/models/query.py", line 671, in create
    obj.save(force_insert=True, using=self.db)
  File "/home/wnico/anaconda3/envs/frb5/lib/python3.10/site-packages/django/db/models/base.py", line 831, in save
    self.save_base(
  File "/home/wnico/anaconda3/envs/frb5/lib/python3.10/site-packages/django/db/models/base.py", line 882, in save_base
    updated = self._save_table(
  File "/home/wnico/anaconda3/envs/frb5/lib/python3.10/site-packages/django/db/models/base.py", line 1025, in _save_table
    results = self._do_insert(
  File "/home/wnico/anaconda3/envs/frb5/lib/python3.10/site-packages/django/db/models/base.py", line 1066, in _do_insert
    return manager._insert(
  File "/home/wnico/anaconda3/envs/frb5/lib/python3.10/site-packages/django/db/models/manager.py", line 85, in manager_method
    return getattr(self.get_queryset(), name)(*args, **kwargs)
  File "/home/wnico/anaconda3/envs/frb5/lib/python3.10/site-packages/django/db/models/query.py", line 1790, in _insert
    return query.get_compiler(using=using).execute_sql(returning_fields)
  File "/home/wnico/anaconda3/envs/frb5/lib/python3.10/site-packages/django/db/models/sql/compiler.py", line 1657, in execute_sql
    cursor.execute(sql, params)
  File "/home/wnico/anaconda3/envs/frb5/lib/python3.10/site-packages/django/db/backends/utils.py", line 103, in execute
    return super().execute(sql, params)
  File "/home/wnico/anaconda3/envs/frb5/lib/python3.10/site-packages/django/db/backends/utils.py", line 67, in execute
    return self._execute_with_wrappers(
  File "/home/wnico/anaconda3/envs/frb5/lib/python3.10/site-packages/django/db/backends/utils.py", line 80, in _execute_with_wrappers
    return executor(sql, params, many, context)
  File "/home/wnico/anaconda3/envs/frb5/lib/python3.10/site-packages/django/db/backends/utils.py", line 84, in _execute
    with self.db.wrap_database_errors:
  File "/home/wnico/anaconda3/envs/frb5/lib/python3.10/site-packages/django/db/utils.py", line 91, in __exit__
    raise dj_exc_value.with_traceback(traceback) from exc_value
  File "/home/wnico/anaconda3/envs/frb5/lib/python3.10/site-packages/django/db/backends/utils.py", line 89, in _execute
    return self.cursor.execute(sql, params)
  File "/home/wnico/anaconda3/envs/frb5/lib/python3.10/site-packages/django/db/backends/sqlite3/base.py", line 357, in execute
    return Database.Cursor.execute(self, query, params)
django.db.utils.IntegrityError: NOT NULL constraint failed: medicalCase_image.case_id
[08/Mar/2024 12:12:05] "POST /medicalCase/upload_pic/ HTTP/1.1" 500 155164
Internal Server Error: /medicalCase/upload_pic/
Traceback (most recent call last):
  File "/home/wnico/anaconda3/envs/frb5/lib/python3.10/site-packages/django/db/backends/utils.py", line 89, in _execute
    return self.cursor.execute(sql, params)
  File "/home/wnico/anaconda3/envs/frb5/lib/python3.10/site-packages/django/db/backends/sqlite3/base.py", line 357, in execute
    return Database.Cursor.execute(self, query, params)
sqlite3.IntegrityError: NOT NULL constraint failed: medicalCase_image.case_id

The above exception was the direct cause of the following exception:

Traceback (most recent call last):
  File "/home/wnico/anaconda3/envs/frb5/lib/python3.10/site-packages/django/core/handlers/exception.py", line 55, in inner
    response = get_response(request)
  File "/home/wnico/anaconda3/envs/frb5/lib/python3.10/site-packages/django/core/handlers/base.py", line 197, in _get_response
    response = wrapped_callback(request, *callback_args, **callback_kwargs)
  File "/home/wnico/anaconda3/envs/frb5/lib/python3.10/site-packages/django/views/decorators/csrf.py", line 54, in wrapped_view
    return view_func(*args, **kwargs)
  File "/mnt/d/MyFileAtD/cancer-prediction/apps/medicalCase/views.py", line 26, in upload_pic
    Image.objects.create(image=saved_pic)
  File "/home/wnico/anaconda3/envs/frb5/lib/python3.10/site-packages/django/db/models/manager.py", line 85, in manager_method
    return getattr(self.get_queryset(), name)(*args, **kwargs)
  File "/home/wnico/anaconda3/envs/frb5/lib/python3.10/site-packages/django/db/models/query.py", line 671, in create
    obj.save(force_insert=True, using=self.db)
  File "/home/wnico/anaconda3/envs/frb5/lib/python3.10/site-packages/django/db/models/base.py", line 831, in save
    self.save_base(
  File "/home/wnico/anaconda3/envs/frb5/lib/python3.10/site-packages/django/db/models/base.py", line 882, in save_base
    updated = self._save_table(
  File "/home/wnico/anaconda3/envs/frb5/lib/python3.10/site-packages/django/db/models/base.py", line 1025, in _save_table
    results = self._do_insert(
  File "/home/wnico/anaconda3/envs/frb5/lib/python3.10/site-packages/django/db/models/base.py", line 1066, in _do_insert
    return manager._insert(
  File "/home/wnico/anaconda3/envs/frb5/lib/python3.10/site-packages/django/db/models/manager.py", line 85, in manager_method
    return getattr(self.get_queryset(), name)(*args, **kwargs)
  File "/home/wnico/anaconda3/envs/frb5/lib/python3.10/site-packages/django/db/models/query.py", line 1790, in _insert
    return query.get_compiler(using=using).execute_sql(returning_fields)
  File "/home/wnico/anaconda3/envs/frb5/lib/python3.10/site-packages/django/db/models/sql/compiler.py", line 1657, in execute_sql
    cursor.execute(sql, params)
  File "/home/wnico/anaconda3/envs/frb5/lib/python3.10/site-packages/django/db/backends/utils.py", line 103, in execute
    return super().execute(sql, params)
  File "/home/wnico/anaconda3/envs/frb5/lib/python3.10/site-packages/django/db/backends/utils.py", line 67, in execute
    return self._execute_with_wrappers(
  File "/home/wnico/anaconda3/envs/frb5/lib/python3.10/site-packages/django/db/backends/utils.py", line 80, in _execute_with_wrappers
    return executor(sql, params, many, context)
  File "/home/wnico/anaconda3/envs/frb5/lib/python3.10/site-packages/django/db/backends/utils.py", line 84, in _execute
    with self.db.wrap_database_errors:
  File "/home/wnico/anaconda3/envs/frb5/lib/python3.10/site-packages/django/db/utils.py", line 91, in __exit__
    raise dj_exc_value.with_traceback(traceback) from exc_value
  File "/home/wnico/anaconda3/envs/frb5/lib/python3.10/site-packages/django/db/backends/utils.py", line 89, in _execute
    return self.cursor.execute(sql, params)
  File "/home/wnico/anaconda3/envs/frb5/lib/python3.10/site-packages/django/db/backends/sqlite3/base.py", line 357, in execute
    return Database.Cursor.execute(self, query, params)
django.db.utils.IntegrityError: NOT NULL constraint failed: medicalCase_image.case_id
[08/Mar/2024 18:12:29] "POST /medicalCase/upload_pic/ HTTP/1.1" 500 155164
/mnt/d/MyFileAtD/cancer-prediction/apps/medicalCase/models.py changed, reloading.
Performing system checks...

System check identified no issues (0 silenced).
March 08, 2024 - 12:12:00
Django version 4.1, using settings 'cancer_prediction_backend.settings'
Starting development server at http://127.0.0.1:8000/
Quit the server with CONTROL-C.
Watching for file changes with StatReloader
Internal Server Error: /medicalCase/upload_pic/
Traceback (most recent call last):
  File "/home/wnico/anaconda3/envs/frb5/lib/python3.10/site-packages/django/db/backends/utils.py", line 89, in _execute
    return self.cursor.execute(sql, params)
  File "/home/wnico/anaconda3/envs/frb5/lib/python3.10/site-packages/django/db/backends/sqlite3/base.py", line 357, in execute
    return Database.Cursor.execute(self, query, params)
sqlite3.IntegrityError: NOT NULL constraint failed: medicalCase_image.case_id

The above exception was the direct cause of the following exception:

Traceback (most recent call last):
  File "/home/wnico/anaconda3/envs/frb5/lib/python3.10/site-packages/django/core/handlers/exception.py", line 55, in inner
    response = get_response(request)
  File "/home/wnico/anaconda3/envs/frb5/lib/python3.10/site-packages/django/core/handlers/base.py", line 197, in _get_response
    response = wrapped_callback(request, *callback_args, **callback_kwargs)
  File "/home/wnico/anaconda3/envs/frb5/lib/python3.10/site-packages/django/views/decorators/csrf.py", line 54, in wrapped_view
    return view_func(*args, **kwargs)
  File "/mnt/d/MyFileAtD/cancer-prediction/apps/medicalCase/views.py", line 26, in upload_pic
    Image.objects.create(image=saved_pic)
  File "/home/wnico/anaconda3/envs/frb5/lib/python3.10/site-packages/django/db/models/manager.py", line 85, in manager_method
    return getattr(self.get_queryset(), name)(*args, **kwargs)
  File "/home/wnico/anaconda3/envs/frb5/lib/python3.10/site-packages/django/db/models/query.py", line 671, in create
    obj.save(force_insert=True, using=self.db)
  File "/home/wnico/anaconda3/envs/frb5/lib/python3.10/site-packages/django/db/models/base.py", line 831, in save
    self.save_base(
  File "/home/wnico/anaconda3/envs/frb5/lib/python3.10/site-packages/django/db/models/base.py", line 882, in save_base
    updated = self._save_table(
  File "/home/wnico/anaconda3/envs/frb5/lib/python3.10/site-packages/django/db/models/base.py", line 1025, in _save_table
    results = self._do_insert(
  File "/home/wnico/anaconda3/envs/frb5/lib/python3.10/site-packages/django/db/models/base.py", line 1066, in _do_insert
    return manager._insert(
  File "/home/wnico/anaconda3/envs/frb5/lib/python3.10/site-packages/django/db/models/manager.py", line 85, in manager_method
    return getattr(self.get_queryset(), name)(*args, **kwargs)
  File "/home/wnico/anaconda3/envs/frb5/lib/python3.10/site-packages/django/db/models/query.py", line 1790, in _insert
    return query.get_compiler(using=using).execute_sql(returning_fields)
  File "/home/wnico/anaconda3/envs/frb5/lib/python3.10/site-packages/django/db/models/sql/compiler.py", line 1657, in execute_sql
    cursor.execute(sql, params)
  File "/home/wnico/anaconda3/envs/frb5/lib/python3.10/site-packages/django/db/backends/utils.py", line 103, in execute
    return super().execute(sql, params)
  File "/home/wnico/anaconda3/envs/frb5/lib/python3.10/site-packages/django/db/backends/utils.py", line 67, in execute
    return self._execute_with_wrappers(
  File "/home/wnico/anaconda3/envs/frb5/lib/python3.10/site-packages/django/db/backends/utils.py", line 80, in _execute_with_wrappers
    return executor(sql, params, many, context)
  File "/home/wnico/anaconda3/envs/frb5/lib/python3.10/site-packages/django/db/backends/utils.py", line 84, in _execute
    with self.db.wrap_database_errors:
  File "/home/wnico/anaconda3/envs/frb5/lib/python3.10/site-packages/django/db/utils.py", line 91, in __exit__
    raise dj_exc_value.with_traceback(traceback) from exc_value
  File "/home/wnico/anaconda3/envs/frb5/lib/python3.10/site-packages/django/db/backends/utils.py", line 89, in _execute
    return self.cursor.execute(sql, params)
  File "/home/wnico/anaconda3/envs/frb5/lib/python3.10/site-packages/django/db/backends/sqlite3/base.py", line 357, in execute
    return Database.Cursor.execute(self, query, params)
django.db.utils.IntegrityError: NOT NULL constraint failed: medicalCase_image.case_id
[08/Mar/2024 18:13:01] "POST /medicalCase/upload_pic/ HTTP/1.1" 500 155164
/mnt/d/MyFileAtD/cancer-prediction/apps/medicalCase/models.py changed, reloading.
Performing system checks...

System check identified no issues (0 silenced).
March 08, 2024 - 18:13:00
Django version 4.1, using settings 'cancer_prediction_backend.settings'
Starting development server at http://127.0.0.1:8000/
Quit the server with CONTROL-C.
Watching for file changes with StatReloader
[08/Mar/2024 18:13:21] "GET /admin/ HTTP/1.1" 200 5803
[08/Mar/2024 18:13:23] "GET /admin/medicalCase/case/ HTTP/1.1" 200 7080
[08/Mar/2024 18:13:23] "GET /admin/jsi18n/ HTTP/1.1" 200 3343
[08/Mar/2024 18:13:23] "GET /admin/medicalCase/case/1/change/ HTTP/1.1" 200 7854
[08/Mar/2024 18:13:23] "GET /admin/jsi18n/ HTTP/1.1" 200 3343
/mnt/d/MyFileAtD/cancer-prediction/apps/medicalCase/views.py changed, reloading.
Performing system checks...

System check identified no issues (0 silenced).
March 08, 2024 - 18:13:14
Django version 4.1, using settings 'cancer_prediction_backend.settings'
Starting development server at http://127.0.0.1:8000/
Quit the server with CONTROL-C.
Watching for file changes with StatReloader
Internal Server Error: /medicalCase/upload_pic/
Traceback (most recent call last):
  File "/home/wnico/anaconda3/envs/frb5/lib/python3.10/site-packages/django/core/handlers/exception.py", line 55, in inner
    response = get_response(request)
  File "/home/wnico/anaconda3/envs/frb5/lib/python3.10/site-packages/django/core/handlers/base.py", line 197, in _get_response
    response = wrapped_callback(request, *callback_args, **callback_kwargs)
  File "/home/wnico/anaconda3/envs/frb5/lib/python3.10/site-packages/django/views/decorators/csrf.py", line 54, in wrapped_view
    return view_func(*args, **kwargs)
  File "/mnt/d/MyFileAtD/cancer-prediction/apps/medicalCase/views.py", line 27, in upload_pic
    Image.save()
TypeError: Model.save() missing 1 required positional argument: 'self'
[08/Mar/2024 18:13:42] "POST /medicalCase/upload_pic/ HTTP/1.1" 500 68909
/mnt/d/MyFileAtD/cancer-prediction/apps/medicalCase/views.py changed, reloading.
Performing system checks...

System check identified no issues (0 silenced).
March 08, 2024 - 18:13:41
Django version 4.1, using settings 'cancer_prediction_backend.settings'
Starting development server at http://127.0.0.1:8000/
Quit the server with CONTROL-C.
Watching for file changes with StatReloader
[08/Mar/2024 18:14:09] "POST /medicalCase/upload_pic/ HTTP/1.1" 200 42
[08/Mar/2024 18:14:14] "GET /admin/medicalCase/image/ HTTP/1.1" 200 7532
[08/Mar/2024 18:14:14] "GET /admin/jsi18n/ HTTP/1.1" 200 3343
[08/Mar/2024 18:14:15] "GET /admin/medicalCase/image/2/change/ HTTP/1.1" 200 8464
[08/Mar/2024 18:14:15] "GET /admin/jsi18n/ HTTP/1.1" 200 3343
[08/Mar/2024 18:14:17] "GET /mnt/d/MyFileAtD/cancer-prediction/media/images/test.jpg HTTP/1.1" 200 9016
[08/Mar/2024 18:14:18] "GET /admin/medicalCase/image/2/change/ HTTP/1.1" 200 8464
[08/Mar/2024 18:14:19] "GET /admin/medicalCase/case/ HTTP/1.1" 200 7080
[08/Mar/2024 18:14:19] "GET /admin/jsi18n/ HTTP/1.1" 200 3343
[08/Mar/2024 18:14:20] "GET /admin/medicalCase/case/1/change/ HTTP/1.1" 200 7854
[08/Mar/2024 18:14:20] "GET /admin/jsi18n/ HTTP/1.1" 200 3343
[08/Mar/2024 18:14:21] "GET /admin/medicalCase/image/ HTTP/1.1" 200 7532
[08/Mar/2024 18:14:21] "GET /admin/jsi18n/ HTTP/1.1" 200 3343
[08/Mar/2024 18:14:22] "GET /admin/medicalCase/image/3/change/ HTTP/1.1" 200 8464
[08/Mar/2024 18:14:22] "GET /admin/jsi18n/ HTTP/1.1" 200 3343
[08/Mar/2024 18:14:23] "GET /admin/medicalCase/image/3/change/ HTTP/1.1" 200 8464
[08/Mar/2024 18:14:24] "GET /admin/medicalCase/image/ HTTP/1.1" 200 7532
[08/Mar/2024 18:14:24] "GET /admin/jsi18n/ HTTP/1.1" 200 3343
[08/Mar/2024 18:14:25] "GET /admin/medicalCase/image/2/change/ HTTP/1.1" 200 8464
[08/Mar/2024 18:14:25] "GET /admin/jsi18n/ HTTP/1.1" 200 3343
/mnt/d/MyFileAtD/cancer-prediction/apps/medicalCase/views.py changed, reloading.
Performing system checks...

System check identified no issues (0 silenced).
March 08, 2024 - 18:14:02
Django version 4.1, using settings 'cancer_prediction_backend.settings'
Starting development server at http://127.0.0.1:8000/
Quit the server with CONTROL-C.
Watching for file changes with StatReloader
/mnt/d/MyFileAtD/cancer-prediction/apps/medicalCase/views.py changed, reloading.
Performing system checks...

System check identified no issues (0 silenced).
March 08, 2024 - 18:14:57
Django version 4.1, using settings 'cancer_prediction_backend.settings'
Starting development server at http://127.0.0.1:8000/
Quit the server with CONTROL-C.
Watching for file changes with StatReloader
[08/Mar/2024 18:15:05] "POST /medicalCase/upload_pic/ HTTP/1.1" 200 42
[08/Mar/2024 18:15:07] "GET /admin/medicalCase/image/ HTTP/1.1" 200 7752
[08/Mar/2024 18:15:08] "GET /admin/jsi18n/ HTTP/1.1" 200 3343
[08/Mar/2024 18:15:08] "GET /admin/medicalCase/image/4/change/ HTTP/1.1" 200 8395
[08/Mar/2024 18:15:08] "GET /admin/jsi18n/ HTTP/1.1" 200 3343
[08/Mar/2024 18:15:10] "GET /admin/medicalCase/image/ HTTP/1.1" 200 7752
[08/Mar/2024 18:15:11] "GET /admin/medicalCase/image/4/change/ HTTP/1.1" 200 8395
[08/Mar/2024 18:15:11] "GET /admin/jsi18n/ HTTP/1.1" 200 3343
[08/Mar/2024 18:15:12] "GET /admin/medicalCase/image/4/delete/ HTTP/1.1" 200 5888
[08/Mar/2024 18:15:12] "GET /static/admin/js/cancel.js HTTP/1.1" 200 884
[08/Mar/2024 18:15:13] "POST /admin/medicalCase/image/4/delete/ HTTP/1.1" 302 0
[08/Mar/2024 18:15:13] "GET /admin/medicalCase/image/ HTTP/1.1" 200 7696
[08/Mar/2024 18:15:13] "GET /admin/jsi18n/ HTTP/1.1" 200 3343
[08/Mar/2024 18:15:19] "GET /admin/medicalCase/image/2/change/ HTTP/1.1" 200 8464
[08/Mar/2024 18:15:19] "GET /admin/jsi18n/ HTTP/1.1" 200 3343
[08/Mar/2024 18:15:22] "GET /admin/medicalCase/image/ HTTP/1.1" 200 7532
[08/Mar/2024 18:15:22] "GET /admin/jsi18n/ HTTP/1.1" 200 3343
[08/Mar/2024 18:15:30] "POST /admin/medicalCase/image/ HTTP/1.1" 200 6154
[08/Mar/2024 18:15:31] "POST /admin/medicalCase/image/ HTTP/1.1" 302 0
[08/Mar/2024 18:15:31] "GET /admin/medicalCase/image/ HTTP/1.1" 200 7227
[08/Mar/2024 18:15:31] "GET /admin/jsi18n/ HTTP/1.1" 200 3343
[08/Mar/2024 18:15:39] "GET /admin/medicalCase/case/ HTTP/1.1" 200 7080
[08/Mar/2024 18:15:39] "GET /admin/jsi18n/ HTTP/1.1" 200 3343
[08/Mar/2024 18:15:40] "GET /admin/medicalCase/image/ HTTP/1.1" 200 7091
[08/Mar/2024 18:15:40] "GET /admin/jsi18n/ HTTP/1.1" 200 3343
[08/Mar/2024 18:15:40] "GET /admin/auth/group/ HTTP/1.1" 200 6254
[08/Mar/2024 18:15:40] "GET /admin/jsi18n/ HTTP/1.1" 200 3343
[08/Mar/2024 18:15:41] "GET /admin/medicalCase/case/ HTTP/1.1" 200 7080
[08/Mar/2024 18:15:41] "GET /admin/jsi18n/ HTTP/1.1" 200 3343
[08/Mar/2024 18:15:42] "GET /admin/user/user/ HTTP/1.1" 200 10228
[08/Mar/2024 18:15:42] "GET /static/admin/img/icon-no.svg HTTP/1.1" 200 560
[08/Mar/2024 18:15:42] "GET /admin/jsi18n/ HTTP/1.1" 200 3343
[08/Mar/2024 18:15:43] "GET /static/admin/img/sorting-icons.svg HTTP/1.1" 200 1097
[08/Mar/2024 18:15:43] "GET /admin/medicalCase/case/ HTTP/1.1" 200 7080
[08/Mar/2024 18:15:43] "GET /admin/jsi18n/ HTTP/1.1" 200 3343
[08/Mar/2024 18:15:49] "GET /admin/user/user/ HTTP/1.1" 200 10228
[08/Mar/2024 18:15:49] "GET /admin/jsi18n/ HTTP/1.1" 200 3343
[08/Mar/2024 18:15:50] "GET /admin/medicalCase/case/ HTTP/1.1" 200 7080
[08/Mar/2024 18:15:50] "GET /admin/jsi18n/ HTTP/1.1" 200 3343
[08/Mar/2024 18:15:51] "GET /admin/auth/group/ HTTP/1.1" 200 6254
[08/Mar/2024 18:15:51] "GET /admin/jsi18n/ HTTP/1.1" 200 3343
[08/Mar/2024 18:15:52] "GET /admin/user/user/ HTTP/1.1" 200 10228
[08/Mar/2024 18:15:52] "GET /admin/jsi18n/ HTTP/1.1" 200 3343
[08/Mar/2024 18:15:53] "GET /admin/medicalCase/case/ HTTP/1.1" 200 7080
[08/Mar/2024 18:15:53] "GET /admin/jsi18n/ HTTP/1.1" 200 3343
[08/Mar/2024 18:16:16] "GET /admin/medicalCase/case/ HTTP/1.1" 200 7080
[08/Mar/2024 18:16:16] "GET /admin/jsi18n/ HTTP/1.1" 200 3343
[08/Mar/2024 18:16:20] "GET /admin/medicalCase/case/1/change/ HTTP/1.1" 200 7854
[08/Mar/2024 18:16:20] "GET /admin/jsi18n/ HTTP/1.1" 200 3343
[08/Mar/2024 18:16:21] "GET /admin/medicalCase/image/ HTTP/1.1" 200 7091
[08/Mar/2024 18:16:21] "GET /admin/jsi18n/ HTTP/1.1" 200 3343
[08/Mar/2024 18:16:23] "GET /admin/medicalCase/image/ HTTP/1.1" 200 7091
[08/Mar/2024 18:16:23] "GET /admin/jsi18n/ HTTP/1.1" 200 3343
[08/Mar/2024 18:16:29] "POST /medicalCase/upload_pic/ HTTP/1.1" 200 42
[08/Mar/2024 18:17:17] "GET /admin/medicalCase/image/ HTTP/1.1" 200 7312
[08/Mar/2024 18:17:17] "GET /admin/jsi18n/ HTTP/1.1" 200 3343
[08/Mar/2024 18:17:17] "GET /admin/medicalCase/image/5/change/ HTTP/1.1" 200 8395
[08/Mar/2024 18:17:17] "GET /admin/jsi18n/ HTTP/1.1" 200 3343
[08/Mar/2024 18:17:18] "GET /media/images/test.jpg HTTP/1.1" 200 9016
[08/Mar/2024 18:17:19] "GET /admin/medicalCase/image/5/change/ HTTP/1.1" 200 8395
[08/Mar/2024 18:17:22] "GET /admin/medicalCase/image/ HTTP/1.1" 200 7312
[08/Mar/2024 18:17:23] "GET /admin/medicalCase/image/5/change/ HTTP/1.1" 200 8395
[08/Mar/2024 18:17:24] "GET /admin/medicalCase/image/ HTTP/1.1" 200 7312
[08/Mar/2024 18:17:26] "GET /admin/medicalCase/image/1/change/ HTTP/1.1" 200 8401
[08/Mar/2024 18:17:26] "GET /admin/jsi18n/ HTTP/1.1" 200 3343
[08/Mar/2024 18:17:28] "GET /admin/medicalCase/image/ HTTP/1.1" 200 7312
[08/Mar/2024 18:17:30] "GET /admin/medicalCase/image/1/change/ HTTP/1.1" 200 8401
[08/Mar/2024 18:37:58] "GET /admin/medicalCase/image/1/change/ HTTP/1.1" 200 8401
[08/Mar/2024 18:37:58] "GET /admin/jsi18n/ HTTP/1.1" 200 3343
/mnt/d/MyFileAtD/cancer-prediction/apps/medicalCase/models.py changed, reloading.
Performing system checks...

System check identified no issues (0 silenced).
March 08, 2024 - 18:15:01
Django version 4.1, using settings 'cancer_prediction_backend.settings'
Starting development server at http://127.0.0.1:8000/
Quit the server with CONTROL-C.
Watching for file changes with StatReloader
/mnt/d/MyFileAtD/cancer-prediction/apps/medicalCase/views.py changed, reloading.
Performing system checks...

System check identified no issues (0 silenced).
March 08, 2024 - 18:45:40
Django version 4.1, using settings 'cancer_prediction_backend.settings'
Starting development server at http://127.0.0.1:8000/
Quit the server with CONTROL-C.
Watching for file changes with StatReloader
/mnt/d/MyFileAtD/cancer-prediction/apps/medicalCase/views.py changed, reloading.
Performing system checks...

System check identified no issues (0 silenced).
March 08, 2024 - 18:45:48
Django version 4.1, using settings 'cancer_prediction_backend.settings'
Starting development server at http://127.0.0.1:8000/
Quit the server with CONTROL-C.
Watching for file changes with StatReloader
/mnt/d/MyFileAtD/cancer-prediction/apps/medicalCase/views.py changed, reloading.
Performing system checks...

System check identified no issues (0 silenced).
March 08, 2024 - 18:46:23
Django version 4.1, using settings 'cancer_prediction_backend.settings'
Starting development server at http://127.0.0.1:8000/
Quit the server with CONTROL-C.
Watching for file changes with StatReloader
/mnt/d/MyFileAtD/cancer-prediction/apps/medicalCase/urls.py changed, reloading.
Performing system checks...

System check identified no issues (0 silenced).
March 08, 2024 - 18:46:30
Django version 4.1, using settings 'cancer_prediction_backend.settings'
Starting development server at http://127.0.0.1:8000/
Quit the server with CONTROL-C.
Watching for file changes with StatReloader
Exception in thread django-main-thread:
Traceback (most recent call last):
  File "/home/wnico/anaconda3/envs/frb5/lib/python3.10/threading.py", line 1016, in _bootstrap_inner
    self.run()
  File "/home/wnico/anaconda3/envs/frb5/lib/python3.10/threading.py", line 953, in run
    self._target(*self._args, **self._kwargs)
  File "/home/wnico/anaconda3/envs/frb5/lib/python3.10/site-packages/django/utils/autoreload.py", line 64, in wrapper
    fn(*args, **kwargs)
  File "/home/wnico/anaconda3/envs/frb5/lib/python3.10/site-packages/django/core/management/commands/runserver.py", line 134, in inner_run
    self.check(display_num_errors=True)
  File "/home/wnico/anaconda3/envs/frb5/lib/python3.10/site-packages/django/core/management/base.py", line 475, in check
    all_issues = checks.run_checks(
  File "/home/wnico/anaconda3/envs/frb5/lib/python3.10/site-packages/django/core/checks/registry.py", line 88, in run_checks
    new_errors = check(app_configs=app_configs, databases=databases)
  File "/home/wnico/anaconda3/envs/frb5/lib/python3.10/site-packages/django/core/checks/urls.py", line 14, in check_url_config
    return check_resolver(resolver)
  File "/home/wnico/anaconda3/envs/frb5/lib/python3.10/site-packages/django/core/checks/urls.py", line 24, in check_resolver
    return check_method()
  File "/home/wnico/anaconda3/envs/frb5/lib/python3.10/site-packages/django/urls/resolvers.py", line 476, in check
    for pattern in self.url_patterns:
  File "/home/wnico/anaconda3/envs/frb5/lib/python3.10/site-packages/django/utils/functional.py", line 57, in __get__
    res = instance.__dict__[self.name] = self.func(instance)
  File "/home/wnico/anaconda3/envs/frb5/lib/python3.10/site-packages/django/urls/resolvers.py", line 690, in url_patterns
    patterns = getattr(self.urlconf_module, "urlpatterns", self.urlconf_module)
  File "/home/wnico/anaconda3/envs/frb5/lib/python3.10/site-packages/django/utils/functional.py", line 57, in __get__
    res = instance.__dict__[self.name] = self.func(instance)
  File "/home/wnico/anaconda3/envs/frb5/lib/python3.10/site-packages/django/urls/resolvers.py", line 683, in urlconf_module
    return import_module(self.urlconf_name)
  File "/home/wnico/anaconda3/envs/frb5/lib/python3.10/importlib/__init__.py", line 126, in import_module
    return _bootstrap._gcd_import(name[level:], package, level)
  File "<frozen importlib._bootstrap>", line 1050, in _gcd_import
  File "<frozen importlib._bootstrap>", line 1027, in _find_and_load
  File "<frozen importlib._bootstrap>", line 1006, in _find_and_load_unlocked
  File "<frozen importlib._bootstrap>", line 688, in _load_unlocked
  File "<frozen importlib._bootstrap_external>", line 883, in exec_module
  File "<frozen importlib._bootstrap>", line 241, in _call_with_frames_removed
  File "/mnt/d/MyFileAtD/cancer-prediction/cancer_prediction_backend/urls.py", line 26, in <module>
    path('medicalCase/', include('apps.medicalCase.urls')),
  File "/home/wnico/anaconda3/envs/frb5/lib/python3.10/site-packages/django/urls/conf.py", line 38, in include
    urlconf_module = import_module(urlconf_module)
  File "/home/wnico/anaconda3/envs/frb5/lib/python3.10/importlib/__init__.py", line 126, in import_module
    return _bootstrap._gcd_import(name[level:], package, level)
  File "<frozen importlib._bootstrap>", line 1050, in _gcd_import
  File "<frozen importlib._bootstrap>", line 1027, in _find_and_load
  File "<frozen importlib._bootstrap>", line 1006, in _find_and_load_unlocked
  File "<frozen importlib._bootstrap>", line 688, in _load_unlocked
  File "<frozen importlib._bootstrap_external>", line 883, in exec_module
  File "<frozen importlib._bootstrap>", line 241, in _call_with_frames_removed
  File "/mnt/d/MyFileAtD/cancer-prediction/apps/medicalCase/urls.py", line 9, in <module>
    path('')
TypeError: _path() missing 1 required positional argument: 'view'
/mnt/d/MyFileAtD/cancer-prediction/apps/medicalCase/urls.py changed, reloading.
Performing system checks...

Watching for file changes with StatReloader
Exception in thread django-main-thread:
Traceback (most recent call last):
  File "/home/wnico/anaconda3/envs/frb5/lib/python3.10/threading.py", line 1016, in _bootstrap_inner
    self.run()
  File "/home/wnico/anaconda3/envs/frb5/lib/python3.10/threading.py", line 953, in run
    self._target(*self._args, **self._kwargs)
  File "/home/wnico/anaconda3/envs/frb5/lib/python3.10/site-packages/django/utils/autoreload.py", line 64, in wrapper
    fn(*args, **kwargs)
  File "/home/wnico/anaconda3/envs/frb5/lib/python3.10/site-packages/django/core/management/commands/runserver.py", line 134, in inner_run
    self.check(display_num_errors=True)
  File "/home/wnico/anaconda3/envs/frb5/lib/python3.10/site-packages/django/core/management/base.py", line 475, in check
    all_issues = checks.run_checks(
  File "/home/wnico/anaconda3/envs/frb5/lib/python3.10/site-packages/django/core/checks/registry.py", line 88, in run_checks
    new_errors = check(app_configs=app_configs, databases=databases)
  File "/home/wnico/anaconda3/envs/frb5/lib/python3.10/site-packages/django/core/checks/urls.py", line 14, in check_url_config
    return check_resolver(resolver)
  File "/home/wnico/anaconda3/envs/frb5/lib/python3.10/site-packages/django/core/checks/urls.py", line 24, in check_resolver
    return check_method()
  File "/home/wnico/anaconda3/envs/frb5/lib/python3.10/site-packages/django/urls/resolvers.py", line 476, in check
    for pattern in self.url_patterns:
  File "/home/wnico/anaconda3/envs/frb5/lib/python3.10/site-packages/django/utils/functional.py", line 57, in __get__
    res = instance.__dict__[self.name] = self.func(instance)
  File "/home/wnico/anaconda3/envs/frb5/lib/python3.10/site-packages/django/urls/resolvers.py", line 690, in url_patterns
    patterns = getattr(self.urlconf_module, "urlpatterns", self.urlconf_module)
  File "/home/wnico/anaconda3/envs/frb5/lib/python3.10/site-packages/django/utils/functional.py", line 57, in __get__
    res = instance.__dict__[self.name] = self.func(instance)
  File "/home/wnico/anaconda3/envs/frb5/lib/python3.10/site-packages/django/urls/resolvers.py", line 683, in urlconf_module
    return import_module(self.urlconf_name)
  File "/home/wnico/anaconda3/envs/frb5/lib/python3.10/importlib/__init__.py", line 126, in import_module
    return _bootstrap._gcd_import(name[level:], package, level)
  File "<frozen importlib._bootstrap>", line 1050, in _gcd_import
  File "<frozen importlib._bootstrap>", line 1027, in _find_and_load
  File "<frozen importlib._bootstrap>", line 1006, in _find_and_load_unlocked
  File "<frozen importlib._bootstrap>", line 688, in _load_unlocked
  File "<frozen importlib._bootstrap_external>", line 883, in exec_module
  File "<frozen importlib._bootstrap>", line 241, in _call_with_frames_removed
  File "/mnt/d/MyFileAtD/cancer-prediction/cancer_prediction_backend/urls.py", line 26, in <module>
    path('medicalCase/', include('apps.medicalCase.urls')),
  File "/home/wnico/anaconda3/envs/frb5/lib/python3.10/site-packages/django/urls/conf.py", line 38, in include
    urlconf_module = import_module(urlconf_module)
  File "/home/wnico/anaconda3/envs/frb5/lib/python3.10/importlib/__init__.py", line 126, in import_module
    return _bootstrap._gcd_import(name[level:], package, level)
  File "<frozen importlib._bootstrap>", line 1050, in _gcd_import
  File "<frozen importlib._bootstrap>", line 1027, in _find_and_load
  File "<frozen importlib._bootstrap>", line 1006, in _find_and_load_unlocked
  File "<frozen importlib._bootstrap>", line 688, in _load_unlocked
  File "<frozen importlib._bootstrap_external>", line 883, in exec_module
  File "<frozen importlib._bootstrap>", line 241, in _call_with_frames_removed
  File "/mnt/d/MyFileAtD/cancer-prediction/apps/medicalCase/urls.py", line 9, in <module>
    path('upload_chunk', )
TypeError: _path() missing 1 required positional argument: 'view'
/mnt/d/MyFileAtD/cancer-prediction/apps/medicalCase/urls.py changed, reloading.
Performing system checks...

Watching for file changes with StatReloader
/mnt/d/MyFileAtD/cancer-prediction/apps/medicalCase/urls.py changed, reloading.
Performing system checks...

System check identified no issues (0 silenced).
March 08, 2024 - 18:47:34
Django version 4.1, using settings 'cancer_prediction_backend.settings'
Starting development server at http://127.0.0.1:8000/
Quit the server with CONTROL-C.
Watching for file changes with StatReloader
/mnt/d/MyFileAtD/cancer-prediction/apps/medicalCase/urls.py changed, reloading.
Performing system checks...

System check identified no issues (0 silenced).
March 08, 2024 - 18:47:41
Django version 4.1, using settings 'cancer_prediction_backend.settings'
Starting development server at http://127.0.0.1:8000/
Quit the server with CONTROL-C.
Watching for file changes with StatReloader
/mnt/d/MyFileAtD/cancer-prediction/apps/medicalCase/views.py changed, reloading.
Performing system checks...

System check identified no issues (0 silenced).
March 08, 2024 - 18:47:47
Django version 4.1, using settings 'cancer_prediction_backend.settings'
Starting development server at http://127.0.0.1:8000/
Quit the server with CONTROL-C.
Watching for file changes with StatReloader
nohup: ignoring input
Watching for file changes with StatReloader
/mnt/d/MyFileAtD/cancer-prediction/cancer_prediction_backend/settings.py changed, reloading.
Performing system checks...

System check identified no issues (0 silenced).
March 15, 2024 - 08:16:36
Django version 4.1, using settings 'cancer_prediction_backend.settings'
Starting development server at http://127.0.0.1:8000/
Quit the server with CONTROL-C.
Watching for file changes with StatReloader
/mnt/d/MyFileAtD/cancer-prediction/cancer_prediction_backend/settings.py changed, reloading.
Performing system checks...

System check identified no issues (0 silenced).
March 15, 2024 - 08:17:10
Django version 4.1, using settings 'cancer_prediction_backend.settings'
Starting development server at http://127.0.0.1:8000/
Quit the server with CONTROL-C.
Watching for file changes with StatReloader
Exception in thread django-main-thread:
Traceback (most recent call last):
  File "/home/wnico/anaconda3/envs/frb5/lib/python3.10/site-packages/django/apps/config.py", line 210, in create
    app_module = import_module(app_name)
  File "/home/wnico/anaconda3/envs/frb5/lib/python3.10/importlib/__init__.py", line 126, in import_module
    return _bootstrap._gcd_import(name[level:], package, level)
  File "<frozen importlib._bootstrap>", line 1050, in _gcd_import
  File "<frozen importlib._bootstrap>", line 1027, in _find_and_load
  File "<frozen importlib._bootstrap>", line 1004, in _find_and_load_unlocked
ModuleNotFoundError: No module named 'fileManager'

During handling of the above exception, another exception occurred:

Traceback (most recent call last):
  File "/home/wnico/anaconda3/envs/frb5/lib/python3.10/threading.py", line 1016, in _bootstrap_inner
    self.run()
  File "/home/wnico/anaconda3/envs/frb5/lib/python3.10/threading.py", line 953, in run
    self._target(*self._args, **self._kwargs)
  File "/home/wnico/anaconda3/envs/frb5/lib/python3.10/site-packages/django/utils/autoreload.py", line 64, in wrapper
    fn(*args, **kwargs)
  File "/home/wnico/anaconda3/envs/frb5/lib/python3.10/site-packages/django/core/management/commands/runserver.py", line 125, in inner_run
    autoreload.raise_last_exception()
  File "/home/wnico/anaconda3/envs/frb5/lib/python3.10/site-packages/django/utils/autoreload.py", line 87, in raise_last_exception
    raise _exception[1]
  File "/home/wnico/anaconda3/envs/frb5/lib/python3.10/site-packages/django/core/management/__init__.py", line 398, in execute
    autoreload.check_errors(django.setup)()
  File "/home/wnico/anaconda3/envs/frb5/lib/python3.10/site-packages/django/utils/autoreload.py", line 64, in wrapper
    fn(*args, **kwargs)
  File "/home/wnico/anaconda3/envs/frb5/lib/python3.10/site-packages/django/__init__.py", line 24, in setup
    apps.populate(settings.INSTALLED_APPS)
  File "/home/wnico/anaconda3/envs/frb5/lib/python3.10/site-packages/django/apps/registry.py", line 91, in populate
    app_config = AppConfig.create(entry)
  File "/home/wnico/anaconda3/envs/frb5/lib/python3.10/site-packages/django/apps/config.py", line 212, in create
    raise ImproperlyConfigured(
django.core.exceptions.ImproperlyConfigured: Cannot import 'fileManager'. Check that 'apps.fileManager.apps.FilemanagerConfig.name' is correct.
/mnt/d/MyFileAtD/cancer-prediction/apps/fileManager/apps.py changed, reloading.
Watching for file changes with StatReloader
/mnt/d/MyFileAtD/cancer-prediction/apps/fileManager/admin.py changed, reloading.
Performing system checks...

System check identified no issues (0 silenced).
March 15, 2024 - 08:18:52
Django version 4.1, using settings 'cancer_prediction_backend.settings'
Starting development server at http://127.0.0.1:8000/
Quit the server with CONTROL-C.
Watching for file changes with StatReloader
/mnt/d/MyFileAtD/cancer-prediction/cancer_prediction_backend/settings.py changed, reloading.
Performing system checks...

System check identified no issues (0 silenced).
March 15, 2024 - 08:19:06
Django version 4.1, using settings 'cancer_prediction_backend.settings'
Starting development server at http://127.0.0.1:8000/
Quit the server with CONTROL-C.
Watching for file changes with StatReloader
/mnt/d/MyFileAtD/cancer-prediction/apps/fileManager/models.py changed, reloading.
Performing system checks...

System check identified no issues (0 silenced).
March 15, 2024 - 08:19:15
Django version 4.1, using settings 'cancer_prediction_backend.settings'
Starting development server at http://127.0.0.1:8000/
Quit the server with CONTROL-C.
Watching for file changes with StatReloader
/mnt/d/MyFileAtD/cancer-prediction/apps/fileManager/models.py changed, reloading.
Performing system checks...

System check identified no issues (0 silenced).
March 15, 2024 - 08:33:10
Django version 4.1, using settings 'cancer_prediction_backend.settings'
Starting development server at http://127.0.0.1:8000/
Quit the server with CONTROL-C.
Watching for file changes with StatReloader
Exception in thread django-main-thread:
Traceback (most recent call last):
  File "/home/wnico/anaconda3/envs/frb5/lib/python3.10/threading.py", line 1016, in _bootstrap_inner
    self.run()
  File "/home/wnico/anaconda3/envs/frb5/lib/python3.10/threading.py", line 953, in run
    self._target(*self._args, **self._kwargs)
  File "/home/wnico/anaconda3/envs/frb5/lib/python3.10/site-packages/django/utils/autoreload.py", line 64, in wrapper
    fn(*args, **kwargs)
  File "/home/wnico/anaconda3/envs/frb5/lib/python3.10/site-packages/django/core/management/commands/runserver.py", line 125, in inner_run
    autoreload.raise_last_exception()
  File "/home/wnico/anaconda3/envs/frb5/lib/python3.10/site-packages/django/utils/autoreload.py", line 87, in raise_last_exception
    raise _exception[1]
  File "/home/wnico/anaconda3/envs/frb5/lib/python3.10/site-packages/django/core/management/__init__.py", line 398, in execute
    autoreload.check_errors(django.setup)()
  File "/home/wnico/anaconda3/envs/frb5/lib/python3.10/site-packages/django/utils/autoreload.py", line 64, in wrapper
    fn(*args, **kwargs)
  File "/home/wnico/anaconda3/envs/frb5/lib/python3.10/site-packages/django/__init__.py", line 24, in setup
    apps.populate(settings.INSTALLED_APPS)
  File "/home/wnico/anaconda3/envs/frb5/lib/python3.10/site-packages/django/apps/registry.py", line 116, in populate
    app_config.import_models()
  File "/home/wnico/anaconda3/envs/frb5/lib/python3.10/site-packages/django/apps/config.py", line 269, in import_models
    self.models_module = import_module(models_module_name)
  File "/home/wnico/anaconda3/envs/frb5/lib/python3.10/importlib/__init__.py", line 126, in import_module
    return _bootstrap._gcd_import(name[level:], package, level)
  File "<frozen importlib._bootstrap>", line 1050, in _gcd_import
  File "<frozen importlib._bootstrap>", line 1027, in _find_and_load
  File "<frozen importlib._bootstrap>", line 1006, in _find_and_load_unlocked
  File "<frozen importlib._bootstrap>", line 688, in _load_unlocked
  File "<frozen importlib._bootstrap_external>", line 879, in exec_module
  File "<frozen importlib._bootstrap_external>", line 1017, in get_code
  File "<frozen importlib._bootstrap_external>", line 947, in source_to_code
  File "<frozen importlib._bootstrap>", line 241, in _call_with_frames_removed
  File "/mnt/d/MyFileAtD/cancer-prediction/apps/fileManager/models.py", line 10
    
    ^
IndentationError: expected an indented block after function definition on line 9
/mnt/d/MyFileAtD/cancer-prediction/apps/fileManager/models.py changed, reloading.
Watching for file changes with StatReloader
/mnt/d/MyFileAtD/cancer-prediction/apps/fileManager/models.py changed, reloading.
Performing system checks...

System check identified no issues (0 silenced).
March 15, 2024 - 08:33:51
Django version 4.1, using settings 'cancer_prediction_backend.settings'
Starting development server at http://127.0.0.1:8000/
Quit the server with CONTROL-C.
Watching for file changes with StatReloader
/mnt/d/MyFileAtD/cancer-prediction/apps/fileManager/models.py changed, reloading.
Performing system checks...

System check identified no issues (0 silenced).
March 15, 2024 - 08:34:18
Django version 4.1, using settings 'cancer_prediction_backend.settings'
Starting development server at http://127.0.0.1:8000/
Quit the server with CONTROL-C.
Watching for file changes with StatReloader
/mnt/d/MyFileAtD/cancer-prediction/apps/fileManager/models.py changed, reloading.
Performing system checks...

System check identified no issues (0 silenced).
March 15, 2024 - 08:34:58
Django version 4.1, using settings 'cancer_prediction_backend.settings'
Starting development server at http://127.0.0.1:8000/
Quit the server with CONTROL-C.
Watching for file changes with StatReloader
/mnt/d/MyFileAtD/cancer-prediction/apps/fileManager/models.py changed, reloading.
Performing system checks...

System check identified no issues (0 silenced).
March 15, 2024 - 08:35:00
Django version 4.1, using settings 'cancer_prediction_backend.settings'
Starting development server at http://127.0.0.1:8000/
Quit the server with CONTROL-C.
Watching for file changes with StatReloader
/mnt/d/MyFileAtD/cancer-prediction/apps/fileManager/models.py changed, reloading.
Performing system checks...

System check identified no issues (0 silenced).
March 15, 2024 - 08:35:07
Django version 4.1, using settings 'cancer_prediction_backend.settings'
Starting development server at http://127.0.0.1:8000/
Quit the server with CONTROL-C.
Watching for file changes with StatReloader
/mnt/d/MyFileAtD/cancer-prediction/apps/fileManager/models.py changed, reloading.
Performing system checks...

System check identified no issues (0 silenced).
March 15, 2024 - 08:35:37
Django version 4.1, using settings 'cancer_prediction_backend.settings'
Starting development server at http://127.0.0.1:8000/
Quit the server with CONTROL-C.
Watching for file changes with StatReloader
/mnt/d/MyFileAtD/cancer-prediction/apps/fileManager/models.py changed, reloading.
Performing system checks...

System check identified no issues (0 silenced).
March 15, 2024 - 08:35:51
Django version 4.1, using settings 'cancer_prediction_backend.settings'
Starting development server at http://127.0.0.1:8000/
Quit the server with CONTROL-C.
Watching for file changes with StatReloader
/mnt/d/MyFileAtD/cancer-prediction/apps/fileManager/models.py changed, reloading.
Performing system checks...

System check identified no issues (0 silenced).
March 15, 2024 - 08:35:57
Django version 4.1, using settings 'cancer_prediction_backend.settings'
Starting development server at http://127.0.0.1:8000/
Quit the server with CONTROL-C.
Watching for file changes with StatReloader
/mnt/d/MyFileAtD/cancer-prediction/apps/fileManager/models.py changed, reloading.
Performing system checks...

System check identified no issues (0 silenced).
March 15, 2024 - 08:36:31
Django version 4.1, using settings 'cancer_prediction_backend.settings'
Starting development server at http://127.0.0.1:8000/
Quit the server with CONTROL-C.
Watching for file changes with StatReloader
/mnt/d/MyFileAtD/cancer-prediction/cancer_prediction_backend/settings.py changed, reloading.
Performing system checks...

System check identified no issues (0 silenced).
March 15, 2024 - 08:36:38
Django version 4.1, using settings 'cancer_prediction_backend.settings'
Starting development server at http://127.0.0.1:8000/
Quit the server with CONTROL-C.
Traceback (most recent call last):
  File "/mnt/d/MyFileAtD/cancer-prediction/manage.py", line 22, in <module>
    main()
  File "/mnt/d/MyFileAtD/cancer-prediction/manage.py", line 18, in main
    execute_from_command_line(sys.argv)
  File "/home/wnico/anaconda3/envs/frb5/lib/python3.10/site-packages/django/core/management/__init__.py", line 446, in execute_from_command_line
    utility.execute()
  File "/home/wnico/anaconda3/envs/frb5/lib/python3.10/site-packages/django/core/management/__init__.py", line 386, in execute
    settings.INSTALLED_APPS
  File "/home/wnico/anaconda3/envs/frb5/lib/python3.10/site-packages/django/conf/__init__.py", line 92, in __getattr__
    self._setup(name)
  File "/home/wnico/anaconda3/envs/frb5/lib/python3.10/site-packages/django/conf/__init__.py", line 79, in _setup
    self._wrapped = Settings(settings_module)
  File "/home/wnico/anaconda3/envs/frb5/lib/python3.10/site-packages/django/conf/__init__.py", line 190, in __init__
    mod = importlib.import_module(self.SETTINGS_MODULE)
  File "/home/wnico/anaconda3/envs/frb5/lib/python3.10/importlib/__init__.py", line 126, in import_module
    return _bootstrap._gcd_import(name[level:], package, level)
  File "<frozen importlib._bootstrap>", line 1050, in _gcd_import
  File "<frozen importlib._bootstrap>", line 1027, in _find_and_load
  File "<frozen importlib._bootstrap>", line 1006, in _find_and_load_unlocked
  File "<frozen importlib._bootstrap>", line 688, in _load_unlocked
  File "<frozen importlib._bootstrap_external>", line 883, in exec_module
  File "<frozen importlib._bootstrap>", line 241, in _call_with_frames_removed
  File "/mnt/d/MyFileAtD/cancer-prediction/cancer_prediction_backend/settings.py", line 20, in <module>
    sys.path.insert(0, str(BASE_DIR / 'apps'))
NameError: name 'sys' is not defined
